Workbook
Name BB_Energy: LISTAS!$F$30:$F$31
Name BRENT: ECONOMICOS!$B$2
Name Ecopetrol: LISTAS!$G$30:$G$32
Name GUNVOR: LISTAS!$E$30:$E$31
Name GUNVOR_Mediano: LISTAS!$H$30:$H$31
Name PALERMO: LISTAS!$G$8:$G$14
Name PETROMIL: LISTAS!$H$8:$H$10
Name Proveedor: LISTAS!$D$30:$D$33
Name PUERTO_BAHIA: LISTAS!$F$8
Name PUERTOS: LISTAS!$C$8:$C$12
Name SPD: LISTAS!$E$8:$E$13
Name TRM: ECONOMICOS!$B$3

Sheet Resultados
A1: CONTRATO | B1: ID | C1: Producto | D1: Proveedor | E1: Volumen Compra BBL | F1: Valor Compra Crudo | G1: Flete Marino | H1: Puerto Llegada | I1: Almacenamiento1 | J1: Oper Portuaria 1 | K1: Costo Ingreso CZF | L1: Remolcador Ingreso CZF | M1: Transporte Terrestre a CZF | N1: Almacenamiento 2 | O1: Oper Portuaria 2 | P1: % Financiación Crudo + Flete Marino | Q1: Valor a Financiar Crudo + Flete | R1: Costo Financiación | S1: Costo Total hasta ingreso TK 109 SPD CZF | T1: USD/BBL CRUDO + FLETE Marino | U1: USD/BBL %FIN mes | V1: USD/BBL Alm+OperPort 1 | W1: Remolcador a CZF | X1: Transp Terrestre a CZF | Y1: USD/BBL Ingreso a CZF (Alm+OperPort 2) | Z1: Nacionalización USD/BBL | AA1: Spread Total on Brent IMPORTACIONES | AB1: Premiun Venta Exportaciones | AC1: Utilidad Exportaciones HC´s ECP u Otros | AD1: Gasto Nacionalización | AE1: Aseguranza Crudo + Flete 0.5% | AF1: Agencia de Aduana | AG1: Inspección Recibido | AH1: Gasto Exportación | AI1: USD/Bbl Exportación | AJ1: Costo Total Exportación | AK1: Spread Exportaciones
A2: =IFERROR(VLOOKUP(B2,LLEGADA!$A$2:$W$17,4,FALSE),0) -> I1-GUNVOR Mediano-LIGHT OIL-100-MBBL-MUSD$7 | B2: =COMPRAS!A2 -> I1 | C2: =IFERROR(VLOOKUP($B2,COMPRAS!$A$2:$D$15,3,0),0) -> LIGHT OIL | D2: =IFERROR(VLOOKUP($B2,COMPRAS!$A$2:$D$15,4,0),0) -> GUNVOR Mediano | E2: =IFERROR(VLOOKUP($B2,COMPRAS!$A$2:$G$15,6,0),0) -> 100000 | F2: =IFERROR(VLOOKUP($B2,COMPRAS!$A$2:$G$15,7,0),0) -> 7000000 | G2: =IFERROR(VLOOKUP($B2,COMPRAS!$A$2:$J$15,9,0),0)*E2 -> 350000 | H2: =IFERROR(VLOOKUP(B2,LLEGADA!$A$2:$X$17,8,0),0) -> PALERMO | I2: =IFERROR(VLOOKUP(B2,LLEGADA!$A$2:$X$17,13,0),0) -> 150000 | J2: =IFERROR(VLOOKUP(B2,LLEGADA!$A$2:$X$17,18,0),0) -> 54990.377 | K2: =IFERROR(VLOOKUP(B2,LLEGADA!$A$2:$X$17,24,0),0) -> 3500 | L2: =IFERROR(VLOOKUP(B2,LLEGADA!$A$2:$X$17,21,0),0) -> 0 | M2: =IFERROR(VLOOKUP(B2,LLEGADA!$A$2:$X$20,23,FALSE),0) -> 184390.24 | N2: =IFERROR(VLOOKUP(B2,LLEGADA!$A$2:$X$17,14,0),0) -> 57750 | O2: =IFERROR(VLOOKUP(B2,LLEGADA!$A$2:$X$17,19,0),0) -> 63238.933 | P2: =ECONOMICOS!$B$4 -> 0.011 | Q2: =+F2+G2 -> 7350000 | R2: =+Q2*P2 -> 80850 | S2: =IF(G2=0,0,+Q2+SUM(I2:O2)+R2+SUM(AE2:AG2)) -> 8009019.6 | T2: =+(Q2/E2)-BRENT -> 5.5 | U2: =(BRENT+T2)*P2 -> 0.8085 | V2: =((I2+J2)/E2) -> 2.0499038 | W2: =L2/E2 -> 0 | X2: =IFERROR(M2/E2,0) -> 1.8439024 | Y2: =+(K2+N2+O2)/E2 -> 1.2448893 | Z2: =(AE2+AF2+AG2+AH2)/E2 -> 0.643 | AA2: =IF(AB2=0,SUM(T2:Z2),0) -> 12.090196 | AB2: =IF(H2="RETORNO CARGA",ECONOMICOS!$B$7,0) -> 0 | AC2: =IF(AB2=0,0,AB2-SUM(T2:Y2)) -> 0 | AD2: =AE2+AF2+AG2+AH2 -> 64300 | AE2: =IF(AB2=0,(Q2)*0.5%,0) -> 36750 | AF2: =IF(AB2=0,Q2*0.3%,0) -> 22050 | AG2: =IF(AB2=0,IF(E2<150000,5500,8500),0) -> 5500 | AH2: =IF(AB2>0,F2*0.35%,0) -> 0 | AI2: =AH2/E2 -> 0 | AJ2: =IF(AI2>0,(AH2+R2+Q2),0) -> 0 | AK2: =IF(AJ2>0,(AJ2/E2)-BRENT,0) -> 0
A3: =IFERROR(VLOOKUP(B3,LLEGADA!$A$2:$W$17,4,FALSE),0) -> I2-GUNVOR Mediano-LIGHT OIL-100-MBBL-MUSD$7 | B3: =COMPRAS!A3 -> I2 | C3: =IFERROR(VLOOKUP($B3,COMPRAS!$A$2:$D$15,3,0),0) -> LIGHT OIL | D3: =IFERROR(VLOOKUP($B3,COMPRAS!$A$2:$D$15,4,0),0) -> GUNVOR Mediano | E3: =IFERROR(VLOOKUP($B3,COMPRAS!$A$2:$G$15,6,0),0) -> 100000 | F3: =IFERROR(VLOOKUP($B3,COMPRAS!$A$2:$G$15,7,0),0) -> 7000000 | G3: =IFERROR(VLOOKUP($B3,COMPRAS!$A$2:$J$15,9,0),0)*E3 -> 350000 | H3: =IFERROR(VLOOKUP(B3,LLEGADA!$A$2:$X$17,8,0),0) -> PUERTO_BAHIA | I3: =IFERROR(VLOOKUP(B3,LLEGADA!$A$2:$X$17,13,0),0) -> 130000 | J3: =IFERROR(VLOOKUP(B3,LLEGADA!$A$2:$X$17,18,0),0) -> 48116.58 | K3: =IFERROR(VLOOKUP(B3,LLEGADA!$A$2:$X$17,24,0),0) -> 3500 | L3: =IFERROR(VLOOKUP(B3,LLEGADA!$A$2:$X$17,21,0),0) -> 0 | M3: =IFERROR(VLOOKUP(B3,LLEGADA!$A$2:$X$20,23,FALSE),0) -> 81951.22 | N3: =IFERROR(VLOOKUP(B3,LLEGADA!$A$2:$X$17,14,0),0) -> 57750 | O3: =IFERROR(VLOOKUP(B3,LLEGADA!$A$2:$X$17,19,0),0) -> 63238.933 | P3: =ECONOMICOS!$B$4 -> 0.011 | Q3: =+F3+G3 -> 7350000 | R3: =+Q3*P3 -> 80850 | S3: =IF(G3=0,0,+Q3+SUM(I3:O3)+R3+SUM(AE3:AG3)) -> 7879706.7 | T3: =+(Q3/E3)-BRENT -> 5.5 | U3: =(BRENT+T3)*P3 -> 0.8085 | V3: =((I3+J3)/E3) -> 1.7811658 | W3: =L3/E3 -> 0 | X3: =IFERROR(M3/E3,0) -> 0.8195122 | Y3: =+(K3+N3+O3)/E3 -> 1.2448893 | Z3: =(AE3+AF3+AG3+AH3)/E3 -> 0.643 | AA3: =IF(AB3=0,SUM(T3:Z3),0) -> 10.797067 | AB3: =IF(H3="RETORNO CARGA",ECONOMICOS!$B$7,0) -> 0 | AC3: =IF(AB3=0,0,AB3-SUM(T3:Y3)) -> 0 | AD3: =AE3+AF3+AG3+AH3 -> 64300 | AE3: =IF(AB3=0,(Q3)*0.5%,0) -> 36750 | AF3: =IF(AB3=0,Q3*0.3%,0) -> 22050 | AG3: =IF(AB3=0,IF(E3<150000,5500,8500),0) -> 5500 | AH3: =IF(AB3>0,F3*0.35%,0) -> 0 | AI3: =AH3/E3 -> 0 | AJ3: =IF(AI3>0,(AH3+R3+Q3),0) -> 0 | AK3: =IF(AJ3>0,(AJ3/E3)-BRENT,0) -> 0
A4: =IFERROR(VLOOKUP(B4,LLEGADA!$A$2:$W$17,4,FALSE),0) -> E1-Ecopetrol (Exportación-Flete asumido cliente)-FUEL OIL-100-MBBL-MUSD$7 | B4: =COMPRAS!A4 -> E1 | C4: =IFERROR(VLOOKUP($B4,COMPRAS!$A$2:$D$15,3,0),0) -> FUEL OIL | D4: =IFERROR(VLOOKUP($B4,COMPRAS!$A$2:$D$15,4,0),0) -> Ecopetrol (Exportación-Flete asumido cliente) | E4: =IFERROR(VLOOKUP($B4,COMPRAS!$A$2:$G$15,6,0),0) -> 100000 | F4: =IFERROR(VLOOKUP($B4,COMPRAS!$A$2:$G$15,7,0),0) -> 7000000 | G4: =IFERROR(VLOOKUP($B4,COMPRAS!$A$2:$J$15,9,0),0)*E4 -> 0 | H4: =IFERROR(VLOOKUP(B4,LLEGADA!$A$2:$X$17,8,0),0) -> RETORNO CARGA | I4: =IFERROR(VLOOKUP(B4,LLEGADA!$A$2:$X$17,13,0),0) -> 0 | J4: =IFERROR(VLOOKUP(B4,LLEGADA!$A$2:$X$17,18,0),0) -> 0 | K4: =IFERROR(VLOOKUP(B4,LLEGADA!$A$2:$X$17,24,0),0) -> 0 | L4: =IFERROR(VLOOKUP(B4,LLEGADA!$A$2:$X$17,21,0),0) -> 0 | M4: =IFERROR(VLOOKUP(B4,LLEGADA!$A$2:$X$20,23,FALSE),0) -> 0 | N4: =IFERROR(VLOOKUP(B4,LLEGADA!$A$2:$X$17,14,0),0) -> 0 | O4: =IFERROR(VLOOKUP(B4,LLEGADA!$A$2:$X$17,19,0),0) -> 0 | P4: =ECONOMICOS!$B$4 -> 0.011 | Q4: =+F4+G4 -> 7000000 | R4: =+Q4*P4 -> 77000 | S4: =IF(G4=0,0,+Q4+SUM(I4:O4)+R4+SUM(AE4:AG4)) -> 0 | T4: =+(Q4/E4)-BRENT -> 2 | U4: =(BRENT+T4)*P4 -> 0.77 | V4: =((I4+J4)/E4) -> 0 | W4: =L4/E4 -> 0 | X4: =IFERROR(M4/E4,0) -> 0 | Y4: =+(K4+N4+O4)/E4 -> 0 | Z4: 0 | AA4: =IF(AB4=0,SUM(T4:Z4),0) -> 0 | AB4: =IF(H4="RETORNO CARGA",ECONOMICOS!$B$7,0) -> 7 | AC4: =IF(AB4=0,0,AB4-SUM(T4:Y4)) -> 4.23 | AD4: 0 | AE4: =IF(AB4=0,(Q4)*0.5%,0) -> 0 | AF4: =IF(AB4=0,Q4*0.3%,0) -> 0 | AG4: =IF(AB4=0,IF(E4<150000,5500,8500),0) -> 0 | AH4: =IF(AB4>0,F4*0.35%,0) -> 24500 | AI4: =AH4/E4 -> 0.245 | AJ4: =IF(AI4>0,(AH4+R4+Q4),0) -> 7101500 | AK4: =IF(AJ4>0,(AJ4/E4)-BRENT,0) -> 3.015
A5: =IFERROR(VLOOKUP(B5,LLEGADA!$A$2:$W$17,4,FALSE),0) -> I3-GUNVOR Mediano-LIGHT OIL-100-MBBL-MUSD$7 | B5: =COMPRAS!A5 -> I3 | C5: =IFERROR(VLOOKUP($B5,COMPRAS!$A$2:$D$15,3,0),0) -> LIGHT OIL | D5: =IFERROR(VLOOKUP($B5,COMPRAS!$A$2:$D$15,4,0),0) -> GUNVOR Mediano | E5: =IFERROR(VLOOKUP($B5,COMPRAS!$A$2:$G$15,6,0),0) -> 100000 | F5: =IFERROR(VLOOKUP($B5,COMPRAS!$A$2:$G$15,7,0),0) -> 7000000 | G5: =IFERROR(VLOOKUP($B5,COMPRAS!$A$2:$J$15,9,0),0)*E5 -> 350000 | H5: =IFERROR(VLOOKUP(B5,LLEGADA!$A$2:$X$17,8,0),0) -> SPD | I5: =IFERROR(VLOOKUP(B5,LLEGADA!$A$2:$X$17,13,0),0) -> 72750 | J5: =IFERROR(VLOOKUP(B5,LLEGADA!$A$2:$X$17,18,0),0) -> 63238.933 | K5: =IFERROR(VLOOKUP(B5,LLEGADA!$A$2:$X$17,24,0),0) -> 0 | L5: =IFERROR(VLOOKUP(B5,LLEGADA!$A$2:$X$17,21,0),0) -> 0 | M5: =IFERROR(VLOOKUP(B5,LLEGADA!$A$2:$X$20,23,FALSE),0) -> 0 | N5: =IFERROR(VLOOKUP(B5,LLEGADA!$A$2:$X$17,14,0),0) -> 0 | O5: =IFERROR(VLOOKUP(B5,LLEGADA!$A$2:$X$17,19,0),0) -> 0 | P5: =ECONOMICOS!$B$4 -> 0.011 | Q5: =+F5+G5 -> 7350000 | R5: =+Q5*P5 -> 80850 | S5: =IF(G5=0,0,+Q5+SUM(I5:O5)+R5+SUM(AE5:AG5)) -> 7631138.9 | T5: =+(Q5/E5)-BRENT -> 5.5 | U5: =(BRENT+T5)*P5 -> 0.8085 | V5: =((I5+J5)/E5) -> 1.3598893 | W5: =L5/E5 -> 0 | X5: =IFERROR(M5/E5,0) -> 0 | Y5: =+(K5+N5+O5)/E5 -> 0 | Z5: =(AE5+AF5+AG5+AH5)/E5 -> 0.643 | AA5: =IF(AB5=0,SUM(T5:Z5),0) -> 8.3113893 | AB5: =IF(H5="RETORNO CARGA",ECONOMICOS!$B$7,0) -> 0 | AC5: =IF(AB5=0,0,AB5-SUM(T5:Y5)) -> 0 | AD5: =AE5+AF5+AG5+AH5 -> 64300 | AE5: =IF(AB5=0,(Q5)*0.5%,0) -> 36750 | AF5: =IF(AB5=0,Q5*0.3%,0) -> 22050 | AG5: =IF(AB5=0,IF(E5<150000,5500,8500),0) -> 5500 | AH5: =IF(AB5>0,F5*0.35%,0) -> 0 | AI5: =AH5/E5 -> 0 | AJ5: =IF(AI5>0,(AH5+R5+Q5),0) -> 0 | AK5: =IF(AJ5>0,(AJ5/E5)-BRENT,0) -> 0
A6: =IFERROR(VLOOKUP(B6,LLEGADA!$A$2:$W$17,4,FALSE),0) -> I4-GUNVOR Mediano-LIGHT OIL-100-MBBL-MUSD$7 | B6: =COMPRAS!A6 -> I4 | C6: =IFERROR(VLOOKUP($B6,COMPRAS!$A$2:$D$15,3,0),0) -> LIGHT OIL | D6: =IFERROR(VLOOKUP($B6,COMPRAS!$A$2:$D$15,4,0),0) -> GUNVOR Mediano | E6: =IFERROR(VLOOKUP($B6,COMPRAS!$A$2:$G$15,6,0),0) -> 100000 | F6: =IFERROR(VLOOKUP($B6,COMPRAS!$A$2:$G$15,7,0),0) -> 7000000 | G6: =IFERROR(VLOOKUP($B6,COMPRAS!$A$2:$J$15,9,0),0)*E6 -> 350000 | H6: =IFERROR(VLOOKUP(B6,LLEGADA!$A$2:$X$17,8,0),0) -> PETROMIL | I6: =IFERROR(VLOOKUP(B6,LLEGADA!$A$2:$X$17,13,0),0) -> 175000 | J6: =IFERROR(VLOOKUP(B6,LLEGADA!$A$2:$X$17,18,0),0) -> 54990.377 | K6: =IFERROR(VLOOKUP(B6,LLEGADA!$A$2:$X$17,24,0),0) -> 0 | L6: =IFERROR(VLOOKUP(B6,LLEGADA!$A$2:$X$17,21,0),0) -> 90000 | M6: =IFERROR(VLOOKUP(B6,LLEGADA!$A$2:$X$20,23,FALSE),0) -> 0 | N6: =IFERROR(VLOOKUP(B6,LLEGADA!$A$2:$X$17,14,0),0) -> 57750 | O6: =IFERROR(VLOOKUP(B6,LLEGADA!$A$2:$X$17,19,0),0) -> 63238.933 | P6: =ECONOMICOS!$B$4 -> 0.011 | Q6: =+F6+G6 -> 7350000 | R6: =+Q6*P6 -> 80850 | S6: =IF(G6=0,0,+Q6+SUM(I6:O6)+R6+SUM(AE6:AG6)) -> 7936129.3 | T6: =+(Q6/E6)-BRENT -> 5.5 | U6: =(BRENT+T6)*P6 -> 0.8085 | V6: =((I6+J6)/E6) -> 2.2999038 | W6: =L6/E6 -> 0.9 | X6: =IFERROR(M6/E6,0) -> 0 | Y6: =+(K6+N6+O6)/E6 -> 1.2098893 | Z6: =(AE6+AF6+AG6+AH6)/E6 -> 0.643 | AA6: =IF(AB6=0,SUM(T6:Z6),0) -> 11.361293 | AB6: =IF(H6="RETORNO CARGA",ECONOMICOS!$B$7,0) -> 0 | AC6: =IF(AB6=0,0,AB6-SUM(T6:Y6)) -> 0 | AD6: =AE6+AF6+AG6+AH6 -> 64300 | AE6: =IF(AB6=0,(Q6)*0.5%,0) -> 36750 | AF6: =IF(AB6=0,Q6*0.3%,0) -> 22050 | AG6: =IF(AB6=0,IF(E6<150000,5500,8500),0) -> 5500 | AH6: =IF(AB6>0,F6*0.35%,0) -> 0 | AI6: =AH6/E6 -> 0 | AJ6: =IF(AI6>0,(AH6+R6+Q6),0) -> 0 | AK6: =IF(AJ6>0,(AJ6/E6)-BRENT,0) -> 0
A7: =IFERROR(VLOOKUP(B7,LLEGADA!$A$2:$W$17,4,FALSE),0) -> I5-GUNVOR-LIGHT OIL-35-MBBL-MUSD$2,45 | B7: =COMPRAS!A7 -> I5 | C7: =IFERROR(VLOOKUP($B7,COMPRAS!$A$2:$D$15,3,0),0) -> LIGHT OIL | D7: =IFERROR(VLOOKUP($B7,COMPRAS!$A$2:$D$15,4,0),0) -> GUNVOR | E7: =IFERROR(VLOOKUP($B7,COMPRAS!$A$2:$G$15,6,0),0) -> 35000 | F7: =IFERROR(VLOOKUP($B7,COMPRAS!$A$2:$G$15,7,0),0) -> 2450000 | G7: =IFERROR(VLOOKUP($B7,COMPRAS!$A$2:$J$15,9,0),0)*E7 -> 140000 | H7: =IFERROR(VLOOKUP(B7,LLEGADA!$A$2:$X$17,8,0),0) -> SPD | I7: =IFERROR(VLOOKUP(B7,LLEGADA!$A$2:$X$17,13,0),0) -> 24750 | J7: =IFERROR(VLOOKUP(B7,LLEGADA!$A$2:$X$17,18,0),0) -> 22133.627 | K7: =IFERROR(VLOOKUP(B7,LLEGADA!$A$2:$X$17,24,0),0) -> 0 | L7: =IFERROR(VLOOKUP(B7,LLEGADA!$A$2:$X$17,21,0),0) -> 0 | M7: =IFERROR(VLOOKUP(B7,LLEGADA!$A$2:$X$20,23,FALSE),0) -> 0 | N7: =IFERROR(VLOOKUP(B7,LLEGADA!$A$2:$X$17,14,0),0) -> 0 | O7: =IFERROR(VLOOKUP(B7,LLEGADA!$A$2:$X$17,19,0),0) -> 0 | P7: =ECONOMICOS!$B$4 -> 0.011 | Q7: =+F7+G7 -> 2590000 | R7: =+Q7*P7 -> 28490 | S7: =IF(G7=0,0,+Q7+SUM(I7:O7)+R7+SUM(AE7:AG7)) -> 2691593.6 | T7: =+(Q7/E7)-BRENT -> 6 | U7: =(BRENT+T7)*P7 -> 0.814 | V7: =((I7+J7)/E7) -> 1.3395322 | W7: =L7/E7 -> 0 | X7: =IFERROR(M7/E7,0) -> 0 | Y7: =+(K7+N7+O7)/E7 -> 0 | Z7: =(AE7+AF7+AG7+AH7)/E7 -> 0.74914286 | AA7: =IF(AB7=0,SUM(T7:Z7),0) -> 8.902675 | AB7: =IF(H7="RETORNO CARGA",ECONOMICOS!$B$7,0) -> 0 | AC7: =IF(AB7=0,0,AB7-SUM(T7:Y7)) -> 0 | AD7: =AE7+AF7+AG7+AH7 -> 26220 | AE7: =IF(AB7=0,(Q7)*0.5%,0) -> 12950 | AF7: =IF(AB7=0,Q7*0.3%,0) -> 7770 | AG7: =IF(AB7=0,IF(E7<150000,5500,8500),0) -> 5500 | AH7: =IF(AB7>0,F7*0.35%,0) -> 0 | AI7: =AH7/E7 -> 0 | AJ7: =IF(AI7>0,(AH7+R7+Q7),0) -> 0 | AK7: =IF(AJ7>0,(AJ7/E7)-BRENT,0) -> 0
A8: =IFERROR(VLOOKUP(B8,LLEGADA!$A$2:$W$17,4,FALSE),0) -> I6-BB Energy-LIGHT OIL-20-MBBL-MUSD$1,44 | B8: =COMPRAS!A8 -> I6 | C8: =IFERROR(VLOOKUP($B8,COMPRAS!$A$2:$D$15,3,0),0) -> LIGHT OIL | D8: =IFERROR(VLOOKUP($B8,COMPRAS!$A$2:$D$15,4,0),0) -> BB Energy | E8: =IFERROR(VLOOKUP($B8,COMPRAS!$A$2:$G$15,6,0),0) -> 20000 | F8: =IFERROR(VLOOKUP($B8,COMPRAS!$A$2:$G$15,7,0),0) -> 1440000 | G8: =IFERROR(VLOOKUP($B8,COMPRAS!$A$2:$J$15,9,0),0)*E8 -> 100000 | H8: =IFERROR(VLOOKUP(B8,LLEGADA!$A$2:$X$17,8,0),0) -> SPD | I8: =IFERROR(VLOOKUP(B8,LLEGADA!$A$2:$X$17,13,0),0) -> 15000 | J8: =IFERROR(VLOOKUP(B8,LLEGADA!$A$2:$X$17,18,0),0) -> 12570.023 | K8: =IFERROR(VLOOKUP(B8,LLEGADA!$A$2:$X$17,24,0),0) -> 0 | L8: =IFERROR(VLOOKUP(B8,LLEGADA!$A$2:$X$17,21,0),0) -> 0 | M8: =IFERROR(VLOOKUP(B8,LLEGADA!$A$2:$X$20,23,FALSE),0) -> 0 | N8: =IFERROR(VLOOKUP(B8,LLEGADA!$A$2:$X$17,14,0),0) -> 0 | O8: =IFERROR(VLOOKUP(B8,LLEGADA!$A$2:$X$17,19,0),0) -> 0 | P8: =ECONOMICOS!$B$4 -> 0.011 | Q8: =+F8+G8 -> 1540000 | R8: =+Q8*P8 -> 16940 | S8: =IF(G8=0,0,+Q8+SUM(I8:O8)+R8+SUM(AE8:AG8)) -> 1602330 | T8: =+(Q8/E8)-BRENT -> 9 | U8: =(BRENT+T8)*P8 -> 0.847 | V8: =((I8+J8)/E8) -> 1.3785012 | W8: =L8/E8 -> 0 | X8: =IFERROR(M8/E8,0) -> 0 | Y8: =+(K8+N8+O8)/E8 -> 0 | Z8: =(AE8+AF8+AG8+AH8)/E8 -> 0.891 | AA8: =IF(AB8=0,SUM(T8:Z8),0) -> 12.116501 | AB8: =IF(H8="RETORNO CARGA",ECONOMICOS!$B$7,0) -> 0 | AC8: =IF(AB8=0,0,AB8-SUM(T8:Y8)) -> 0 | AD8: =AE8+AF8+AG8+AH8 -> 17820 | AE8: =IF(AB8=0,(Q8)*0.5%,0) -> 7700 | AF8: =IF(AB8=0,Q8*0.3%,0) -> 4620 | AG8: =IF(AB8=0,IF(E8<150000,5500,8500),0) -> 5500 | AH8: =IF(AB8>0,F8*0.35%,0) -> 0 | AI8: =AH8/E8 -> 0 | AJ8: =IF(AI8>0,(AH8+R8+Q8),0) -> 0 | AK8: =IF(AJ8>0,(AJ8/E8)-BRENT,0) -> 0
A9: =IFERROR(VLOOKUP(B9,LLEGADA!$A$2:$W$17,4,FALSE),0) -> I7-GUNVOR Mediano-LIGHT OIL-300-MBBL-MUSD$20,4 | B9: =COMPRAS!A9 -> I7 | C9: =IFERROR(VLOOKUP($B9,COMPRAS!$A$2:$D$15,3,0),0) -> LIGHT OIL | D9: =IFERROR(VLOOKUP($B9,COMPRAS!$A$2:$D$15,4,0),0) -> GUNVOR Mediano | E9: =IFERROR(VLOOKUP($B9,COMPRAS!$A$2:$G$15,6,0),0) -> 300000 | F9: =IFERROR(VLOOKUP($B9,COMPRAS!$A$2:$G$15,7,0),0) -> 20400000 | G9: =IFERROR(VLOOKUP($B9,COMPRAS!$A$2:$J$15,9,0),0)*E9 -> 600000 | H9: =IFERROR(VLOOKUP(B9,LLEGADA!$A$2:$X$17,8,0),0) -> PUERTO_BAHIA | I9: =IFERROR(VLOOKUP(B9,LLEGADA!$A$2:$X$17,13,0),0) -> 390000 | J9: =IFERROR(VLOOKUP(B9,LLEGADA!$A$2:$X$17,18,0),0) -> 154753.13 | K9: =IFERROR(VLOOKUP(B9,LLEGADA!$A$2:$X$17,24,0),0) -> 10500 | L9: =IFERROR(VLOOKUP(B9,LLEGADA!$A$2:$X$17,21,0),0) -> 0 | M9: =IFERROR(VLOOKUP(B9,LLEGADA!$A$2:$X$20,23,FALSE),0) -> 245853.66 | N9: =IFERROR(VLOOKUP(B9,LLEGADA!$A$2:$X$17,14,0),0) -> 153750 | O9: =IFERROR(VLOOKUP(B9,LLEGADA!$A$2:$X$17,19,0),0) -> 203389.83 | P9: =ECONOMICOS!$B$4 -> 0.011 | Q9: =+F9+G9 -> 21000000 | R9: =+Q9*P9 -> 231000 | S9: =IF(G9=0,0,+Q9+SUM(I9:O9)+R9+SUM(AE9:AG9)) -> 22565747 | T9: =+(Q9/E9)-BRENT -> 2 | U9: =(BRENT+T9)*P9 -> 0.77 | V9: =((I9+J9)/E9) -> 1.8158438 | W9: =L9/E9 -> 0 | X9: =IFERROR(M9/E9,0) -> 0.8195122 | Y9: =+(K9+N9+O9)/E9 -> 1.2254661 | Z9: =(AE9+AF9+AG9+AH9)/E9 -> 0.58833333 | AA9: =IF(AB9=0,SUM(T9:Z9),0) -> 7.2191554 | AB9: =IF(H9="RETORNO CARGA",ECONOMICOS!$B$7,0) -> 0 | AC9: =IF(AB9=0,0,AB9-SUM(T9:Y9)) -> 0 | AD9: =AE9+AF9+AG9+AH9 -> 176500 | AE9: =IF(AB9=0,(Q9)*0.5%,0) -> 105000 | AF9: =IF(AB9=0,Q9*0.3%,0) -> 63000 | AG9: =IF(AB9=0,IF(E9<150000,5500,8500),0) -> 8500 | AH9: =IF(AB9>0,F9*0.35%,0) -> 0 | AI9: =AH9/E9 -> 0 | AJ9: =IF(AI9>0,(AH9+R9+Q9),0) -> 0 | AK9: =IF(AJ9>0,(AJ9/E9)-BRENT,0) -> 0
A10: =IFERROR(VLOOKUP(B10,LLEGADA!$A$2:$W$17,4,FALSE),0) -> I8-GUNVOR-LIGHT OIL-50-MBBL-MUSD$3,5 | B10: =COMPRAS!A10 -> I8 | C10: =IFERROR(VLOOKUP($B10,COMPRAS!$A$2:$D$15,3,0),0) -> LIGHT OIL | D10: =IFERROR(VLOOKUP($B10,COMPRAS!$A$2:$D$15,4,0),0) -> GUNVOR | E10: =IFERROR(VLOOKUP($B10,COMPRAS!$A$2:$G$15,6,0),0) -> 50000 | F10: =IFERROR(VLOOKUP($B10,COMPRAS!$A$2:$G$15,7,0),0) -> 3500000 | G10: =IFERROR(VLOOKUP($B10,COMPRAS!$A$2:$J$15,9,0),0)*E10 -> 200000 | H10: =IFERROR(VLOOKUP(B10,LLEGADA!$A$2:$X$17,8,0),0) -> SPD | I10: =IFERROR(VLOOKUP(B10,LLEGADA!$A$2:$X$17,13,0),0) -> 33750 | J10: =IFERROR(VLOOKUP(B10,LLEGADA!$A$2:$X$17,18,0),0) -> 32011.134 | K10: =IFERROR(VLOOKUP(B10,LLEGADA!$A$2:$X$17,24,0),0) -> 0 | L10: =IFERROR(VLOOKUP(B10,LLEGADA!$A$2:$X$17,21,0),0) -> 0 | M10: =IFERROR(VLOOKUP(B10,LLEGADA!$A$2:$X$20,23,FALSE),0) -> 0 | N10: =IFERROR(VLOOKUP(B10,LLEGADA!$A$2:$X$17,14,0),0) -> 0 | O10: =IFERROR(VLOOKUP(B10,LLEGADA!$A$2:$X$17,19,0),0) -> 0 | P10: =ECONOMICOS!$B$4 -> 0.011 | Q10: =+F10+G10 -> 3700000 | R10: =+Q10*P10 -> 40700 | S10: =IF(G10=0,0,+Q10+SUM(I10:O10)+R10+SUM(AE10:AG10)) -> 3841561.1 | T10: =+(Q10/E10)-BRENT -> 6 | U10: =(BRENT+T10)*P10 -> 0.814 | V10: =((I10+J10)/E10) -> 1.3152227 | W10: =L10/E10 -> 0 | X10: =IFERROR(M10/E10,0) -> 0 | Y10: =+(K10+N10+O10)/E10 -> 0 | Z10: =(AE10+AF10+AG10+AH10)/E10 -> 0.702 | AA10: =IF(AB10=0,SUM(T10:Z10),0) -> 8.8312227 | AB10: =IF(H10="RETORNO CARGA",ECONOMICOS!$B$7,0) -> 0 | AC10: =IF(AB10=0,0,AB10-SUM(T10:Y10)) -> 0 | AD10: =AE10+AF10+AG10+AH10 -> 35100 | AE10: =IF(AB10=0,(Q10)*0.5%,0) -> 18500 | AF10: =IF(AB10=0,Q10*0.3%,0) -> 11100 | AG10: =IF(AB10=0,IF(E10<150000,5500,8500),0) -> 5500 | AH10: =IF(AB10>0,F10*0.35%,0) -> 0 | AI10: =AH10/E10 -> 0 | AJ10: =IF(AI10>0,(AH10+R10+Q10),0) -> 0 | AK10: =IF(AJ10>0,(AJ10/E10)-BRENT,0) -> 0
A11: =IFERROR(VLOOKUP(B11,LLEGADA!$A$2:$W$17,4,FALSE),0) -> I9-BB Energy-LIGHT OIL-75-MBBL-MUSD$5,2875 | B11: =COMPRAS!A11 -> I9 | C11: =IFERROR(VLOOKUP($B11,COMPRAS!$A$2:$D$15,3,0),0) -> LIGHT OIL | D11: =IFERROR(VLOOKUP($B11,COMPRAS!$A$2:$D$15,4,0),0) -> BB Energy | E11: =IFERROR(VLOOKUP($B11,COMPRAS!$A$2:$G$15,6,0),0) -> 75000 | F11: =IFERROR(VLOOKUP($B11,COMPRAS!$A$2:$G$15,7,0),0) -> 5287500 | G11: =IFERROR(VLOOKUP($B11,COMPRAS!$A$2:$J$15,9,0),0)*E11 -> 300000 | H11: =IFERROR(VLOOKUP(B11,LLEGADA!$A$2:$X$17,8,0),0) -> SPD | I11: =IFERROR(VLOOKUP(B11,LLEGADA!$A$2:$X$17,13,0),0) -> 60750 | J11: =IFERROR(VLOOKUP(B11,LLEGADA!$A$2:$X$17,18,0),0) -> 48618.94 | K11: =IFERROR(VLOOKUP(B11,LLEGADA!$A$2:$X$17,24,0),0) -> 0 | L11: =IFERROR(VLOOKUP(B11,LLEGADA!$A$2:$X$17,21,0),0) -> 0 | M11: =IFERROR(VLOOKUP(B11,LLEGADA!$A$2:$X$20,23,FALSE),0) -> 0 | N11: =IFERROR(VLOOKUP(B11,LLEGADA!$A$2:$X$17,14,0),0) -> 0 | O11: =IFERROR(VLOOKUP(B11,LLEGADA!$A$2:$X$17,19,0),0) -> 0 | P11: =ECONOMICOS!$B$4 -> 0.011 | Q11: =+F11+G11 -> 5587500 | R11: =+Q11*P11 -> 61462.5 | S11: =IF(G11=0,0,+Q11+SUM(I11:O11)+R11+SUM(AE11:AG11)) -> 5808531.4 | T11: =+(Q11/E11)-BRENT -> 6.5 | U11: =(BRENT+T11)*P11 -> 0.8195 | V11: =((I11+J11)/E11) -> 1.4582525 | W11: =L11/E11 -> 0 | X11: =IFERROR(M11/E11,0) -> 0 | Y11: =+(K11+N11+O11)/E11 -> 0 | Z11: =(AE11+AF11+AG11+AH11)/E11 -> 0.66933333 | AA11: =IF(AB11=0,SUM(T11:Z11),0) -> 9.4470859 | AB11: =IF(H11="RETORNO CARGA",ECONOMICOS!$B$7,0) -> 0 | AC11: =IF(AB11=0,0,AB11-SUM(T11:Y11)) -> 0 | AD11: =AE11+AF11+AG11+AH11 -> 50200 | AE11: =IF(AB11=0,(Q11)*0.5%,0) -> 27937.5 | AF11: =IF(AB11=0,Q11*0.3%,0) -> 16762.5 | AG11: =IF(AB11=0,IF(E11<150000,5500,8500),0) -> 5500 | AH11: =IF(AB11>0,F11*0.35%,0) -> 0 | AI11: =AH11/E11 -> 0 | AJ11: =IF(AI11>0,(AH11+R11+Q11),0) -> 0 | AK11: =IF(AJ11>0,(AJ11/E11)-BRENT,0) -> 0
A12: =IFERROR(VLOOKUP(B12,LLEGADA!$A$2:$W$17,4,FALSE),0) -> I10-GUNVOR Mediano-LIGHT OIL-15-MBBL-MUSD$1,065 | B12: =COMPRAS!A12 -> I10 | C12: =IFERROR(VLOOKUP($B12,COMPRAS!$A$2:$D$15,3,0),0) -> LIGHT OIL | D12: =IFERROR(VLOOKUP($B12,COMPRAS!$A$2:$D$15,4,0),0) -> GUNVOR Mediano | E12: =IFERROR(VLOOKUP($B12,COMPRAS!$A$2:$G$15,6,0),0) -> 15000 | F12: =IFERROR(VLOOKUP($B12,COMPRAS!$A$2:$G$15,7,0),0) -> 1065000 | G12: =IFERROR(VLOOKUP($B12,COMPRAS!$A$2:$J$15,9,0),0)*E12 -> 75000 | H12: =IFERROR(VLOOKUP(B12,LLEGADA!$A$2:$X$17,8,0),0) -> PALERMO | I12: =IFERROR(VLOOKUP(B12,LLEGADA!$A$2:$X$17,13,0),0) -> 22500 | J12: =IFERROR(VLOOKUP(B12,LLEGADA!$A$2:$X$17,18,0),0) -> 8350.7307 | K12: =IFERROR(VLOOKUP(B12,LLEGADA!$A$2:$X$17,24,0),0) -> 525 | L12: =IFERROR(VLOOKUP(B12,LLEGADA!$A$2:$X$17,21,0),0) -> 0 | M12: =IFERROR(VLOOKUP(B12,LLEGADA!$A$2:$X$20,23,FALSE),0) -> 27658.537 | N12: =IFERROR(VLOOKUP(B12,LLEGADA!$A$2:$X$17,14,0),0) -> 11250 | O12: =IFERROR(VLOOKUP(B12,LLEGADA!$A$2:$X$17,19,0),0) -> 9603.3403 | P12: =ECONOMICOS!$B$4 -> 0.011 | Q12: =+F12+G12 -> 1140000 | R12: =+Q12*P12 -> 12540 | S12: =IF(G12=0,0,+Q12+SUM(I12:O12)+R12+SUM(AE12:AG12)) -> 1247047.6 | T12: =+(Q12/E12)-BRENT -> 8 | U12: =(BRENT+T12)*P12 -> 0.836 | V12: =((I12+J12)/E12) -> 2.0567154 | W12: =L12/E12 -> 0 | X12: =IFERROR(M12/E12,0) -> 1.8439024 | Y12: =+(K12+N12+O12)/E12 -> 1.4252227 | Z12: =(AE12+AF12+AG12+AH12)/E12 -> 0.97466667 | AA12: =IF(AB12=0,SUM(T12:Z12),0) -> 15.136507 | AB12: =IF(H12="RETORNO CARGA",ECONOMICOS!$B$7,0) -> 0 | AC12: =IF(AB12=0,0,AB12-SUM(T12:Y12)) -> 0 | AD12: =AE12+AF12+AG12+AH12 -> 14620 | AE12: =IF(AB12=0,(Q12)*0.5%,0) -> 5700 | AF12: =IF(AB12=0,Q12*0.3%,0) -> 3420 | AG12: =IF(AB12=0,IF(E12<150000,5500,8500),0) -> 5500 | AH12: =IF(AB12>0,F12*0.35%,0) -> 0 | AI12: =AH12/E12 -> 0 | AJ12: =IF(AI12>0,(AH12+R12+Q12),0) -> 0 | AK12: =IF(AJ12>0,(AJ12/E12)-BRENT,0) -> 0
A13: =IFERROR(VLOOKUP(B13,LLEGADA!$A$2:$W$17,4,FALSE),0) -> I11-BB Energy-LIGHT OIL-200-MBBL-MUSD$13,6 | B13: =COMPRAS!A13 -> I11 | C13: =IFERROR(VLOOKUP($B13,COMPRAS!$A$2:$D$15,3,0),0) -> LIGHT OIL | D13: =IFERROR(VLOOKUP($B13,COMPRAS!$A$2:$D$15,4,0),0) -> BB Energy | E13: =IFERROR(VLOOKUP($B13,COMPRAS!$A$2:$G$15,6,0),0) -> 200000 | F13: =IFERROR(VLOOKUP($B13,COMPRAS!$A$2:$G$15,7,0),0) -> 13600000 | G13: =IFERROR(VLOOKUP($B13,COMPRAS!$A$2:$J$15,9,0),0)*E13 -> 600000 | H13: =IFERROR(VLOOKUP(B13,LLEGADA!$A$2:$X$17,8,0),0) -> PETROMIL | I13: =IFERROR(VLOOKUP(B13,LLEGADA!$A$2:$X$17,13,0),0) -> 265000 | J13: =IFERROR(VLOOKUP(B13,LLEGADA!$A$2:$X$17,18,0),0) -> 114893.01 | K13: =IFERROR(VLOOKUP(B13,LLEGADA!$A$2:$X$17,24,0),0) -> 0 | L13: =IFERROR(VLOOKUP(B13,LLEGADA!$A$2:$X$17,21,0),0) -> 180000 | M13: =IFERROR(VLOOKUP(B13,LLEGADA!$A$2:$X$20,23,FALSE),0) -> 0 | N13: =IFERROR(VLOOKUP(B13,LLEGADA!$A$2:$X$17,14,0),0) -> 105750 | O13: =IFERROR(VLOOKUP(B13,LLEGADA!$A$2:$X$17,19,0),0) -> 132126.96 | P13: =ECONOMICOS!$B$4 -> 0.011 | Q13: =+F13+G13 -> 14200000 | R13: =+Q13*P13 -> 156200 | S13: =IF(G13=0,0,+Q13+SUM(I13:O13)+R13+SUM(AE13:AG13)) -> 15276070 | T13: =+(Q13/E13)-BRENT -> 3 | U13: =(BRENT+T13)*P13 -> 0.781 | V13: =((I13+J13)/E13) -> 1.899465 | W13: =L13/E13 -> 0.9 | X13: =IFERROR(M13/E13,0) -> 0 | Y13: =+(K13+N13+O13)/E13 -> 1.1893848 | Z13: =(AE13+AF13+AG13+AH13)/E13 -> 0.6105 | AA13: =IF(AB13=0,SUM(T13:Z13),0) -> 8.3803498 | AB13: =IF(H13="RETORNO CARGA",ECONOMICOS!$B$7,0) -> 0 | AC13: =IF(AB13=0,0,AB13-SUM(T13:Y13)) -> 0 | AD13: =AE13+AF13+AG13+AH13 -> 122100 | AE13: =IF(AB13=0,(Q13)*0.5%,0) -> 71000 | AF13: =IF(AB13=0,Q13*0.3%,0) -> 42600 | AG13: =IF(AB13=0,IF(E13<150000,5500,8500),0) -> 8500 | AH13: =IF(AB13>0,F13*0.35%,0) -> 0 | AI13: =AH13/E13 -> 0 | AJ13: =IF(AI13>0,(AH13+R13+Q13),0) -> 0 | AK13: =IF(AJ13>0,(AJ13/E13)-BRENT,0) -> 0
A14: =IFERROR(VLOOKUP(B14,LLEGADA!$A$2:$W$17,4,FALSE),0) -> I12-GUNVOR-LIGHT OIL-50-MBBL-MUSD$3,55 | B14: =COMPRAS!A14 -> I12 | C14: =IFERROR(VLOOKUP($B14,COMPRAS!$A$2:$D$15,3,0),0) -> LIGHT OIL | D14: =IFERROR(VLOOKUP($B14,COMPRAS!$A$2:$D$15,4,0),0) -> GUNVOR | E14: =IFERROR(VLOOKUP($B14,COMPRAS!$A$2:$G$15,6,0),0) -> 50000 | F14: =IFERROR(VLOOKUP($B14,COMPRAS!$A$2:$G$15,7,0),0) -> 3550000 | G14: =IFERROR(VLOOKUP($B14,COMPRAS!$A$2:$J$15,9,0),0)*E14 -> 200000 | H14: =IFERROR(VLOOKUP(B14,LLEGADA!$A$2:$X$17,8,0),0) -> SPD | I14: =IFERROR(VLOOKUP(B14,LLEGADA!$A$2:$X$17,13,0),0) -> 33750 | J14: =IFERROR(VLOOKUP(B14,LLEGADA!$A$2:$X$17,18,0),0) -> 32011.134 | K14: =IFERROR(VLOOKUP(B14,LLEGADA!$A$2:$X$17,24,0),0) -> 0 | L14: =IFERROR(VLOOKUP(B14,LLEGADA!$A$2:$X$17,21,0),0) -> 0 | M14: =IFERROR(VLOOKUP(B14,LLEGADA!$A$2:$X$20,23,FALSE),0) -> 0 | N14: =IFERROR(VLOOKUP(B14,LLEGADA!$A$2:$X$17,14,0),0) -> 0 | O14: =IFERROR(VLOOKUP(B14,LLEGADA!$A$2:$X$17,19,0),0) -> 0 | P14: =ECONOMICOS!$B$4 -> 0.011 | Q14: =+F14+G14 -> 3750000 | R14: =+Q14*P14 -> 41250 | S14: =IF(G14=0,0,+Q14+SUM(I14:O14)+R14+SUM(AE14:AG14)) -> 3892511.1 | T14: =+(Q14/E14)-BRENT -> 7 | U14: =(BRENT+T14)*P14 -> 0.825 | V14: =((I14+J14)/E14) -> 1.3152227 | W14: =L14/E14 -> 0 | X14: =IFERROR(M14/E14,0) -> 0 | Y14: =+(K14+N14+O14)/E14 -> 0 | Z14: =(AE14+AF14+AG14+AH14)/E14 -> 0.71 | AA14: =IF(AB14=0,SUM(T14:Z14),0) -> 9.8502227 | AB14: =IF(H14="RETORNO CARGA",ECONOMICOS!$B$7,0) -> 0 | AC14: =IF(AB14=0,0,AB14-SUM(T14:Y14)) -> 0 | AD14: =AE14+AF14+AG14+AH14 -> 35500 | AE14: =IF(AB14=0,(Q14)*0.5%,0) -> 18750 | AF14: =IF(AB14=0,Q14*0.3%,0) -> 11250 | AG14: =IF(AB14=0,IF(E14<150000,5500,8500),0) -> 5500 | AH14: =IF(AB14>0,F14*0.35%,0) -> 0 | AI14: =AH14/E14 -> 0 | AJ14: =IF(AI14>0,(AH14+R14+Q14),0) -> 0 | AK14: =IF(AJ14>0,(AJ14/E14)-BRENT,0) -> 0
A15: =IFERROR(VLOOKUP(B15,LLEGADA!$A$2:$W$17,4,FALSE),0) -> 0 | B15: =COMPRAS!A15 -> 0 | C15: =IFERROR(VLOOKUP($B15,COMPRAS!$A$2:$D$15,3,0),0) -> 0 | D15: =IFERROR(VLOOKUP($B15,COMPRAS!$A$2:$D$15,4,0),0) -> 0 | E15: =IFERROR(VLOOKUP($B15,COMPRAS!$A$2:$G$15,6,0),0) -> 0 | F15: =IFERROR(VLOOKUP($B15,COMPRAS!$A$2:$G$15,7,0),0) -> 0 | G15: =IFERROR(VLOOKUP($B15,COMPRAS!$A$2:$J$15,9,0),0)*E15 -> 0 | H15: =IFERROR(VLOOKUP(B15,LLEGADA!$A$2:$X$17,8,0),0) -> 0 | I15: =IFERROR(VLOOKUP(B15,LLEGADA!$A$2:$X$17,13,0),0) -> 0 | J15: =IFERROR(VLOOKUP(B15,LLEGADA!$A$2:$X$17,18,0),0) -> 0 | K15: =IFERROR(VLOOKUP(B15,LLEGADA!$A$2:$X$17,24,0),0) -> 0 | L15: =IFERROR(VLOOKUP(B15,LLEGADA!$A$2:$X$17,21,0),0) -> 0 | M15: =IFERROR(VLOOKUP(B15,LLEGADA!$A$2:$X$20,23,FALSE),0) -> 0 | N15: =IFERROR(VLOOKUP(B15,LLEGADA!$A$2:$X$17,14,0),0) -> 0 | O15: =IFERROR(VLOOKUP(B15,LLEGADA!$A$2:$X$17,19,0),0) -> 0 | P15: =ECONOMICOS!$B$4 -> 0.011 | Q15: =+F15+G15 -> 0 | R15: =+Q15*P15 -> 0 | S15: =IF(G15=0,0,+Q15+SUM(I15:O15)+R15+SUM(AE15:AG15)) -> 0 | AH15: =IF(AB15>0,F15*0.4%,0) -> 0 | AJ15: =IF(AI15>0,(AH15+R15+Q15),0) -> 0
A16: =IFERROR(VLOOKUP(B16,LLEGADA!$A$2:$W$17,4,FALSE),0) -> 0 | B16: =COMPRAS!A16 -> 0 | C16: =IFERROR(VLOOKUP($B16,COMPRAS!$A$2:$D$15,3,0),0) -> 0 | D16: =IFERROR(VLOOKUP($B16,COMPRAS!$A$2:$D$15,4,0),0) -> 0 | E16: =IFERROR(VLOOKUP($B16,COMPRAS!$A$2:$G$15,6,0),0) -> 0 | F16: =IFERROR(VLOOKUP($B16,COMPRAS!$A$2:$G$15,7,0),0) -> 0 | G16: =IFERROR(VLOOKUP($B16,COMPRAS!$A$2:$J$15,9,0),0)*E16 -> 0 | H16: =IFERROR(VLOOKUP(B16,LLEGADA!$A$2:$X$17,8,0),0) -> 0 | I16: =IFERROR(VLOOKUP(B16,LLEGADA!$A$2:$X$17,13,0),0) -> 0 | J16: =IFERROR(VLOOKUP(B16,LLEGADA!$A$2:$X$17,18,0),0) -> 0 | K16: =IFERROR(VLOOKUP(B16,LLEGADA!$A$2:$X$17,24,0),0) -> 0 | L16: =IFERROR(VLOOKUP(B16,LLEGADA!$A$2:$X$17,21,0),0) -> 0 | M16: =IFERROR(VLOOKUP(B16,LLEGADA!$A$2:$X$20,23,FALSE),0) -> 0 | N16: =IFERROR(VLOOKUP(B16,LLEGADA!$A$2:$X$17,14,0),0) -> 0 | O16: =IFERROR(VLOOKUP(B16,LLEGADA!$A$2:$X$17,19,0),0) -> 0 | P16: =ECONOMICOS!$B$4 -> 0.011 | Q16: =+F16+G16 -> 0 | R16: =+Q16*P16 -> 0 | S16: =+Q16+SUM(I16:O16) -> 0 | AJ16: =IF(AI16>0,(AH16+R16+Q16),0) -> 0
D17: =IFERROR(VLOOKUP($B17,COMPRAS!$A$2:$D$15,4,0),0) -> 0 | F17: =IFERROR(VLOOKUP($B17,COMPRAS!$A$2:$G$15,7,0),0) -> 0 | G17: =IFERROR(VLOOKUP($B17,COMPRAS!$A$2:$J$15,9,0),0)*E17 -> 0 | AJ17: =IF(AI17>0,(AH17+R17+Q17),0) -> 0

Sheet LLEGADA
A1: ID | B1: PAÍS ORIGEN | C1: Proveedor | D1: PRODUCTO COMPRA | E1: Volumen de compra bpm | F1: °API | G1: FC Bbl/Ton | H1: PUERTO LLEGADA | I1: TK Recibo | J1: Volumen Almace | K1: # Rotaciones1 | L1: #Rotaciones2 | M1: Costo Almacenamiento 1 | N1: Costo Almacenamiento2 | O1: 1ra Vuelta | P1: 2da Vuelta | Q1: 3ra Vuelta | R1: Costo OperPort1 | S1: Costo OperPort2 | T1: OPER PORTUARIO | U1: USO Remocaldor Ingreso CZF | V1: Costo Ingreso CZF Bbl | W1: Logistica Terrestre a CZF | X1: Tramites Ingreso CZF
A2: =+COMPRAS!A2 -> I1 | C2: =+VLOOKUP($A2,COMPRAS!$A$2:$D$17,3,0) -> LIGHT OIL | D2: =+VLOOKUP($A2,COMPRAS!$A$2:$D$17,2,0) -> I1-GUNVOR Mediano-LIGHT OIL-100-MBBL-MUSD$7 | E2: =VLOOKUP(A2,COMPRAS!$A$2:$F$22,6,0) -> 100000 | F2: =VLOOKUP(A2, COMPRAS!$A$2:$N$21, 11, FALSE) -> 32 | G2: =VLOOKUP(A2, COMPRAS!$A$2:$N$21, 14, FALSE) -> 7.274 | H2: PALERMO | I2: PAL-1_168K, PAL-5_80K | J2: =IFERROR(__xludf.DUMMYFUNCTION("IFERROR(SUM(FILTER(PuertosLlegada!$E$2:$E$18, REGEXMATCH(PuertosLlegada!$C$2:$C$18, TEXTJOIN(""|"", TRUE, SPLIT(LLEGADA!I2, "", ""))))),0)"),248000) -> 248000 | K2: =IFERROR(IF((E2/J2)>0<1,1,(E2/J2)),0) -> 0.40322581 | L2: =IFERROR(IF(OR(H2="SPD",J2=0),0,E2/SUMIF(PuertosLlegada!$C$2:$C$18,"TK-109_25K",PuertosLlegada!$E$2:$E$18)),0) -> 4 | M2: =IFERROR((MIN(1,K2)*J2*O2)+(IF(K2-1<0,0,MIN(K2-1,2))*J2*P2)+(IF(K2-2<0,0,K2-2)*J2*Q2),0) -> 150000 | N2: =(MIN(1,L2)*0.75*25000)+IF(L2>1,(MIN(2,L2-1)-1)*0.6*25000,0)+IF(L2>2,(L2-2)*25000*0.48,0) -> 57750 | O2: =IFERROR(VLOOKUP($H2,PuertosLlegada!$B$2:$K$18,5,0),0) -> 1.5 | P2: =IFERROR(VLOOKUP($H2,PuertosLlegada!$B$2:$K$18,6,0),0) -> 0.8 | Q2: =IFERROR(VLOOKUP($H2,PuertosLlegada!$B$2:$K$18,7,0),0) -> 0.8 | R2: =IFERROR((E2/G2)*(T2),0) -> 54990.377 | S2: =IF(L2=0,0,VLOOKUP("SPD",PuertosLlegada!$B$2:$K$18,8,0)*E2/G2) -> 63238.933 | T2: =IFERROR(VLOOKUP($H2,PuertosLlegada!$B$2:$K$18,8,0),0) -> 4 | U2: =IF(H2="PETROMIL",0.9*E2,0) -> 0 | V2: =IFERROR(VLOOKUP($H2,PuertosLlegada!$B$2:$K$18,10,0),0) -> 0 | W2: =IFERROR(VLOOKUP(H2,PuertosLlegada!$B$2:$N$18,13,0)*E2,0)*IF(U2>0,0,1) -> 184390.24 | X2: =IFERROR(E2*IF(W2=0,0,0.035),0) -> 3500
A3: =+COMPRAS!A3 -> I2 | C3: =+VLOOKUP(A3,COMPRAS!$A$2:$D$17,3,0) -> LIGHT OIL | D3: =+VLOOKUP($A3,COMPRAS!$A$2:$D$17,2,0) -> I2-GUNVOR Mediano-LIGHT OIL-100-MBBL-MUSD$7 | E3: =VLOOKUP(A3,COMPRAS!$A$2:$F$22,6,0) -> 100000 | F3: =VLOOKUP(A3, COMPRAS!$A$2:$N$21, 11, FALSE) -> 32 | G3: =VLOOKUP(A3, COMPRAS!$A$2:$N$21, 14, FALSE) -> 7.274 | H3: PUERTO_BAHIA | I3: BAHIA-1_300K | J3: =IFERROR(__xludf.DUMMYFUNCTION("IFERROR(SUM(FILTER(PuertosLlegada!$E$2:$E$18, REGEXMATCH(PuertosLlegada!$C$2:$C$18, TEXTJOIN(""|"", TRUE, SPLIT(LLEGADA!I3, "", ""))))),0)"),300000) -> 300000 | K3: =IFERROR(IF((E3/J3)>0<1,1,(E3/J3)),0) -> 0.33333333 | L3: =IFERROR(IF(OR(H3="SPD",J3=0),0,E3/SUMIF(PuertosLlegada!$C$2:$C$18,"TK-109_25K",PuertosLlegada!$E$2:$E$18)),0) -> 4 | M3: =IFERROR((MIN(1,K3)*J3*O3)+(IF(K3-1<0,0,MIN(K3-1,2))*J3*P3)+(IF(K3-2<0,0,K3-2)*J3*Q3),0) -> 130000 | N3: =(MIN(1,L3)*0.75*25000)+IF(L3>1,(MIN(2,L3-1)-1)*0.6*25000,0)+IF(L3>2,(L3-2)*25000*0.48,0) -> 57750 | O3: =IFERROR(VLOOKUP($H3,PuertosLlegada!$B$2:$K$18,5,0),0) -> 1.3 | P3: =IFERROR(VLOOKUP($H3,PuertosLlegada!$B$2:$K$18,6,0),0) -> 0.8 | Q3: =IFERROR(VLOOKUP($H3,PuertosLlegada!$B$2:$K$18,7,0),0) -> 0.8 | R3: =IFERROR((E3/G3)*(T3),0) -> 48116.58 | S3: =IF(L3=0,0,VLOOKUP("SPD",PuertosLlegada!$B$2:$K$18,8,0)*E3/G3) -> 63238.933 | T3: =IFERROR(VLOOKUP($H3,PuertosLlegada!$B$2:$K$18,8,0),0) -> 3.5 | U3: =IF(H3="PETROMIL",0.9*E3,0) -> 0 | V3: =IFERROR(VLOOKUP($H3,PuertosLlegada!$B$2:$K$18,10,0),0) -> 0 | W3: =IFERROR(VLOOKUP(H3,PuertosLlegada!$B$2:$N$18,13,0)*E3,0)*IF(U3>0,0,1) -> 81951.22 | X3: =IFERROR(E3*IF(W3=0,0,0.035),0) -> 3500
A4: =+COMPRAS!A4 -> E1 | C4: =+VLOOKUP(A4,COMPRAS!$A$2:$D$17,3,0) -> FUEL OIL | D4: =+VLOOKUP($A4,COMPRAS!$A$2:$D$17,2,0) -> E1-Ecopetrol (Exportación-Flete asumido cliente)-FUEL OIL-100-MBBL-MUSD$7 | E4: =VLOOKUP(A4,COMPRAS!$A$2:$F$22,6,0) -> 100000 | F4: =VLOOKUP(A4, COMPRAS!$A$2:$N$21, 11, FALSE) -> 16 | G4: =VLOOKUP(A4, COMPRAS!$A$2:$N$21, 14, FALSE) -> 6.562 | H4: RETORNO CARGA | J4: =IFERROR(__xludf.DUMMYFUNCTION("IFERROR(SUM(FILTER(PuertosLlegada!$E$2:$E$18, REGEXMATCH(PuertosLlegada!$C$2:$C$18, TEXTJOIN(""|"", TRUE, SPLIT(LLEGADA!I4, "", ""))))),0)"),0) -> 0 | K4: =IFERROR(IF((E4/J4)>0<1,1,(E4/J4)),0) -> 0 | L4: =IFERROR(IF(OR(H4="SPD",J4=0),0,E4/SUMIF(PuertosLlegada!$C$2:$C$18,"TK-109_25K",PuertosLlegada!$E$2:$E$18)),0) -> 0 | M4: =IFERROR((MIN(1,K4)*J4*O4)+(IF(K4-1<0,0,MIN(K4-1,2))*J4*P4)+(IF(K4-2<0,0,K4-2)*J4*Q4),0) -> 0 | N4: =(MIN(1,L4)*0.75*25000)+IF(L4>1,(MIN(2,L4-1)-1)*0.6*25000,0)+IF(L4>2,(L4-2)*25000*0.48,0) -> 0 | O4: =IFERROR(VLOOKUP($H4,PuertosLlegada!$B$2:$K$18,5,0),0) -> 0 | P4: =IFERROR(VLOOKUP($H4,PuertosLlegada!$B$2:$K$18,6,0),0) -> 0 | Q4: =IFERROR(VLOOKUP($H4,PuertosLlegada!$B$2:$K$18,7,0),0) -> 0 | R4: =IFERROR((E4/G4)*(T4),0) -> 0 | S4: =IF(L4=0,0,VLOOKUP("SPD",PuertosLlegada!$B$2:$K$18,8,0)*E4/G4) -> 0 | T4: =IFERROR(VLOOKUP($H4,PuertosLlegada!$B$2:$K$18,8,0),0) -> 0 | U4: =IF(H4="PETROMIL",0.9*E4,0) -> 0 | V4: =IFERROR(VLOOKUP($H4,PuertosLlegada!$B$2:$K$18,10,0),0) -> 0 | W4: =IFERROR(VLOOKUP(H4,PuertosLlegada!$B$2:$N$18,13,0)*E4,0)*IF(U4>0,0,1) -> 0 | X4: =IFERROR(E4*IF(W4=0,0,0.035),0) -> 0
A5: =+COMPRAS!A5 -> I3 | C5: =+VLOOKUP(A5,COMPRAS!$A$2:$D$17,3,0) -> LIGHT OIL | D5: =+VLOOKUP($A5,COMPRAS!$A$2:$D$17,2,0) -> I3-GUNVOR Mediano-LIGHT OIL-100-MBBL-MUSD$7 | E5: =VLOOKUP(A5,COMPRAS!$A$2:$F$22,6,0) -> 100000 | F5: =VLOOKUP(A5, COMPRAS!$A$2:$N$21, 11, FALSE) -> 32 | G5: =VLOOKUP(A5, COMPRAS!$A$2:$N$21, 14, FALSE) -> 7.274 | H5: SPD | I5: TK-109_25K | J5: =IFERROR(__xludf.DUMMYFUNCTION("IFERROR(SUM(FILTER(PuertosLlegada!$E$2:$E$18, REGEXMATCH(PuertosLlegada!$C$2:$C$18, TEXTJOIN(""|"", TRUE, SPLIT(LLEGADA!I5, "", ""))))),0)"),25000) -> 25000 | K5: =IFERROR(IF((E5/J5)>0<1,1,(E5/J5)),0) -> 4 | L5: =IFERROR(IF(OR(H5="SPD",J5=0),0,E5/SUMIF(PuertosLlegada!$C$2:$C$18,"TK-109_25K",PuertosLlegada!$E$2:$E$18)),0) -> 0 | M5: =IFERROR((MIN(1,K5)*J5*O5)+(IF(K5-1<0,0,MIN(K5-1,2))*J5*P5)+(IF(K5-2<0,0,K5-2)*J5*Q5),0) -> 72750 | N5: =(MIN(1,L5)*0.75*25000)+IF(L5>1,(MIN(2,L5-1)-1)*0.6*25000,0)+IF(L5>2,(L5-2)*25000*0.48,0) -> 0 | O5: =IFERROR(VLOOKUP($H5,PuertosLlegada!$B$2:$K$18,5,0),0) -> 0.75 | P5: =IFERROR(VLOOKUP($H5,PuertosLlegada!$B$2:$K$18,6,0),0) -> 0.6 | Q5: =IFERROR(VLOOKUP($H5,PuertosLlegada!$B$2:$K$18,7,0),0) -> 0.48 | R5: =IFERROR((E5/G5)*(T5),0) -> 63238.933 | S5: =IF(L5=0,0,VLOOKUP("SPD",PuertosLlegada!$B$2:$K$18,8,0)*E5/G5) -> 0 | T5: =IFERROR(VLOOKUP($H5,PuertosLlegada!$B$2:$K$18,8,0),0) -> 4.6 | U5: =IF(H5="PETROMIL",0.9*E5,0) -> 0 | V5: =IFERROR(VLOOKUP($H5,PuertosLlegada!$B$2:$K$18,10,0),0) -> 0.035 | W5: =IFERROR(VLOOKUP(H5,PuertosLlegada!$B$2:$N$18,13,0)*E5,0)*IF(U5>0,0,1) -> 0 | X5: =IFERROR(E5*IF(W5=0,0,0.035),0) -> 0
A6: =+COMPRAS!A6 -> I4 | C6: =+VLOOKUP(A6,COMPRAS!$A$2:$D$17,3,0) -> LIGHT OIL | D6: =+VLOOKUP($A6,COMPRAS!$A$2:$D$17,2,0) -> I4-GUNVOR Mediano-LIGHT OIL-100-MBBL-MUSD$7 | E6: =VLOOKUP(A6,COMPRAS!$A$2:$F$22,6,0) -> 100000 | F6: =VLOOKUP(A6, COMPRAS!$A$2:$N$21, 11, FALSE) -> 32 | G6: =VLOOKUP(A6, COMPRAS!$A$2:$N$21, 14, FALSE) -> 7.274 | H6: PETROMIL | I6: PAL-1_168K | J6: =IFERROR(__xludf.DUMMYFUNCTION("IFERROR(SUM(FILTER(PuertosLlegada!$E$2:$E$18, REGEXMATCH(PuertosLlegada!$C$2:$C$18, TEXTJOIN(""|"", TRUE, SPLIT(LLEGADA!I6, "", ""))))),0)"),168000) -> 168000 | K6: =IFERROR(IF((E6/J6)>0<1,1,(E6/J6)),0) -> 0.5952381 | L6: =IFERROR(IF(OR(H6="SPD",J6=0),0,E6/SUMIF(PuertosLlegada!$C$2:$C$18,"TK-109_25K",PuertosLlegada!$E$2:$E$18)),0) -> 4 | M6: =IFERROR((MIN(1,K6)*J6*O6)+(IF(K6-1<0,0,MIN(K6-1,2))*J6*P6)+(IF(K6-2<0,0,K6-2)*J6*Q6),0) -> 175000 | N6: =(MIN(1,L6)*0.75*25000)+IF(L6>1,(MIN(2,L6-1)-1)*0.6*25000,0)+IF(L6>2,(L6-2)*25000*0.48,0) -> 57750 | O6: =IFERROR(VLOOKUP($H6,PuertosLlegada!$B$2:$K$18,5,0),0) -> 1.75 | P6: =IFERROR(VLOOKUP($H6,PuertosLlegada!$B$2:$K$18,6,0),0) -> 0.8 | Q6: =IFERROR(VLOOKUP($H6,PuertosLlegada!$B$2:$K$18,7,0),0) -> 0.8 | R6: =IFERROR((E6/G6)*(T6),0) -> 54990.377 | S6: =IF(L6=0,0,VLOOKUP("SPD",PuertosLlegada!$B$2:$K$18,8,0)*E6/G6) -> 63238.933 | T6: =IFERROR(VLOOKUP($H6,PuertosLlegada!$B$2:$K$18,8,0),0) -> 4 | U6: =IF(H6="PETROMIL",0.9*E6,0) -> 90000 | V6: =IFERROR(VLOOKUP($H6,PuertosLlegada!$B$2:$K$18,10,0),0) -> 0 | W6: =IFERROR(VLOOKUP(H6,PuertosLlegada!$B$2:$N$18,13,0)*E6,0)*IF(U6>0,0,1) -> 0 | X6: =IFERROR(E6*IF(W6=0,0,0.035),0) -> 0
A7: =+COMPRAS!A7 -> I5 | C7: =+VLOOKUP(A7,COMPRAS!$A$2:$D$17,3,0) -> LIGHT OIL | D7: =+VLOOKUP($A7,COMPRAS!$A$2:$D$17,2,0) -> I5-GUNVOR-LIGHT OIL-35-MBBL-MUSD$2,45 | E7: =VLOOKUP(A7,COMPRAS!$A$2:$F$22,6,0) -> 35000 | F7: =VLOOKUP(A7, COMPRAS!$A$2:$N$21, 11, FALSE) -> 32 | G7: =VLOOKUP(A7, COMPRAS!$A$2:$N$21, 14, FALSE) -> 7.274 | H7: SPD | I7: TK-109_25K | J7: =IFERROR(__xludf.DUMMYFUNCTION("IFERROR(SUM(FILTER(PuertosLlegada!$E$2:$E$18, REGEXMATCH(PuertosLlegada!$C$2:$C$18, TEXTJOIN(""|"", TRUE, SPLIT(LLEGADA!I7, "", ""))))),0)"),25000) -> 25000 | K7: =IFERROR(IF((E7/J7)>0<1,1,(E7/J7)),0) -> 1.4 | L7: =IFERROR(IF(OR(H7="SPD",J7=0),0,E7/SUMIF(PuertosLlegada!$C$2:$C$18,"TK-109_25K",PuertosLlegada!$E$2:$E$18)),0) -> 0 | M7: =IFERROR((MIN(1,K7)*J7*O7)+(IF(K7-1<0,0,MIN(K7-1,2))*J7*P7)+(IF(K7-2<0,0,K7-2)*J7*Q7),0) -> 24750 | N7: =(MIN(1,L7)*0.75*25000)+IF(L7>1,(MIN(2,L7-1)-1)*0.6*25000,0)+IF(L7>2,(L7-2)*25000*0.48,0) -> 0 | O7: =IFERROR(VLOOKUP($H7,PuertosLlegada!$B$2:$K$18,5,0),0) -> 0.75 | P7: =IFERROR(VLOOKUP($H7,PuertosLlegada!$B$2:$K$18,6,0),0) -> 0.6 | Q7: =IFERROR(VLOOKUP($H7,PuertosLlegada!$B$2:$K$18,7,0),0) -> 0.48 | R7: =IFERROR((E7/G7)*(T7),0) -> 22133.627 | S7: =IF(L7=0,0,VLOOKUP("SPD",PuertosLlegada!$B$2:$K$18,8,0)*E7/G7) -> 0 | T7: =IFERROR(VLOOKUP($H7,PuertosLlegada!$B$2:$K$18,8,0),0) -> 4.6 | U7: =IF(H7="PETROMIL",0.9*E7,0) -> 0 | V7: =IFERROR(VLOOKUP($H7,PuertosLlegada!$B$2:$K$18,10,0),0) -> 0.035 | W7: =IFERROR(VLOOKUP(H7,PuertosLlegada!$B$2:$N$18,13,0)*E7,0)*IF(U7>0,0,1) -> 0 | X7: =IFERROR(E7*IF(W7=0,0,0.035),0) -> 0
A8: =+COMPRAS!A8 -> I6 | C8: =+VLOOKUP(A8,COMPRAS!$A$2:$D$17,3,0) -> LIGHT OIL | D8: =+VLOOKUP($A8,COMPRAS!$A$2:$D$17,2,0) -> I6-BB Energy-LIGHT OIL-20-MBBL-MUSD$1,44 | E8: =VLOOKUP(A8,COMPRAS!$A$2:$F$22,6,0) -> 20000 | F8: =VLOOKUP(A8, COMPRAS!$A$2:$N$21, 11, FALSE) -> 33 | G8: =VLOOKUP(A8, COMPRAS!$A$2:$N$21, 14, FALSE) -> 7.319 | H8: SPD | I8: TK-109_25K | J8: =IFERROR(__xludf.DUMMYFUNCTION("IFERROR(SUM(FILTER(PuertosLlegada!$E$2:$E$18, REGEXMATCH(PuertosLlegada!$C$2:$C$18, TEXTJOIN(""|"", TRUE, SPLIT(LLEGADA!I8, "", ""))))),0)"),25000) -> 25000 | K8: =IFERROR(IF((E8/J8)>0<1,1,(E8/J8)),0) -> 0.8 | L8: =IFERROR(IF(OR(H8="SPD",J8=0),0,E8/SUMIF(PuertosLlegada!$C$2:$C$18,"TK-109_25K",PuertosLlegada!$E$2:$E$18)),0) -> 0 | M8: =IFERROR((MIN(1,K8)*J8*O8)+(IF(K8-1<0,0,MIN(K8-1,2))*J8*P8)+(IF(K8-2<0,0,K8-2)*J8*Q8),0) -> 15000 | N8: =(MIN(1,L8)*0.75*25000)+IF(L8>1,(MIN(2,L8-1)-1)*0.6*25000,0)+IF(L8>2,(L8-2)*25000*0.48,0) -> 0 | O8: =IFERROR(VLOOKUP($H8,PuertosLlegada!$B$2:$K$18,5,0),0) -> 0.75 | P8: =IFERROR(VLOOKUP($H8,PuertosLlegada!$B$2:$K$18,6,0),0) -> 0.6 | Q8: =IFERROR(VLOOKUP($H8,PuertosLlegada!$B$2:$K$18,7,0),0) -> 0.48 | R8: =IFERROR((E8/G8)*(T8),0) -> 12570.023 | S8: =IF(L8=0,0,VLOOKUP("SPD",PuertosLlegada!$B$2:$K$18,8,0)*E8/G8) -> 0 | T8: =IFERROR(VLOOKUP($H8,PuertosLlegada!$B$2:$K$18,8,0),0) -> 4.6 | U8: =IF(H8="PETROMIL",0.9*E8,0) -> 0 | V8: =IFERROR(VLOOKUP($H8,PuertosLlegada!$B$2:$K$18,10,0),0) -> 0.035 | W8: =IFERROR(VLOOKUP(H8,PuertosLlegada!$B$2:$N$18,13,0)*E8,0)*IF(U8>0,0,1) -> 0 | X8: =IFERROR(E8*IF(W8=0,0,0.035),0) -> 0
A9: =+COMPRAS!A9 -> I7 | C9: =+VLOOKUP(A9,COMPRAS!$A$2:$D$17,3,0) -> LIGHT OIL | D9: =+VLOOKUP($A9,COMPRAS!$A$2:$D$17,2,0) -> I7-GUNVOR Mediano-LIGHT OIL-300-MBBL-MUSD$20,4 | E9: =VLOOKUP(A9,COMPRAS!$A$2:$F$22,6,0) -> 300000 | F9: =VLOOKUP(A9, COMPRAS!$A$2:$N$21, 11, FALSE) -> 21 | G9: =VLOOKUP(A9, COMPRAS!$A$2:$N$21, 14, FALSE) -> 6.785 | H9: PUERTO_BAHIA | I9: BAHIA-1_300K | J9: =IFERROR(__xludf.DUMMYFUNCTION("IFERROR(SUM(FILTER(PuertosLlegada!$E$2:$E$18, REGEXMATCH(PuertosLlegada!$C$2:$C$18, TEXTJOIN(""|"", TRUE, SPLIT(LLEGADA!I9, "", ""))))),0)"),300000) -> 300000 | K9: =IFERROR(IF((E9/J9)>0<1,1,(E9/J9)),0) -> 1 | L9: =IFERROR(IF(OR(H9="SPD",J9=0),0,E9/SUMIF(PuertosLlegada!$C$2:$C$18,"TK-109_25K",PuertosLlegada!$E$2:$E$18)),0) -> 12 | M9: =IFERROR((MIN(1,K9)*J9*O9)+(IF(K9-1<0,0,MIN(K9-1,2))*J9*P9)+(IF(K9-2<0,0,K9-2)*J9*Q9),0) -> 390000 | N9: =(MIN(1,L9)*0.75*25000)+IF(L9>1,(MIN(2,L9-1)-1)*0.6*25000,0)+IF(L9>2,(L9-2)*25000*0.48,0) -> 153750 | O9: =IFERROR(VLOOKUP($H9,PuertosLlegada!$B$2:$K$18,5,0),0) -> 1.3 | P9: =IFERROR(VLOOKUP($H9,PuertosLlegada!$B$2:$K$18,6,0),0) -> 0.8 | Q9: =IFERROR(VLOOKUP($H9,PuertosLlegada!$B$2:$K$18,7,0),0) -> 0.8 | R9: =IFERROR((E9/G9)*(T9),0) -> 154753.13 | S9: =IF(L9=0,0,VLOOKUP("SPD",PuertosLlegada!$B$2:$K$18,8,0)*E9/G9) -> 203389.83 | T9: =IFERROR(VLOOKUP($H9,PuertosLlegada!$B$2:$K$18,8,0),0) -> 3.5 | U9: =IF(H9="PETROMIL",0.9*E9,0) -> 0 | V9: =IFERROR(VLOOKUP($H9,PuertosLlegada!$B$2:$K$18,10,0),0) -> 0 | W9: =IFERROR(VLOOKUP(H9,PuertosLlegada!$B$2:$N$18,13,0)*E9,0)*IF(U9>0,0,1) -> 245853.66 | X9: =IFERROR(E9*IF(W9=0,0,0.035),0) -> 10500
A10: =+COMPRAS!A10 -> I8 | C10: =+VLOOKUP(A10,COMPRAS!$A$2:$D$17,3,0) -> LIGHT OIL | D10: =+VLOOKUP($A10,COMPRAS!$A$2:$D$17,2,0) -> I8-GUNVOR-LIGHT OIL-50-MBBL-MUSD$3,5 | E10: =VLOOKUP(A10,COMPRAS!$A$2:$F$22,6,0) -> 50000 | F10: =VLOOKUP(A10, COMPRAS!$A$2:$N$21, 11, FALSE) -> 30 | G10: =VLOOKUP(A10, COMPRAS!$A$2:$N$21, 14, FALSE) -> 7.185 | H10: SPD | I10: TK-109_25K | J10: =IFERROR(__xludf.DUMMYFUNCTION("IFERROR(SUM(FILTER(PuertosLlegada!$E$2:$E$18, REGEXMATCH(PuertosLlegada!$C$2:$C$18, TEXTJOIN(""|"", TRUE, SPLIT(LLEGADA!I10, "", ""))))),0)"),25000) -> 25000 | K10: =IFERROR(IF((E10/J10)>0<1,1,(E10/J10)),0) -> 2 | L10: =IFERROR(IF(OR(H10="SPD",J10=0),0,E10/SUMIF(PuertosLlegada!$C$2:$C$18,"TK-109_25K",PuertosLlegada!$E$2:$E$18)),0) -> 0 | M10: =(MIN(1,K10)*J10*O10)+(IF(K10-1<0,0,MIN(K10-1,2))*J10*P10)+(IF(K10-2<0,0,K10-2)*J10*Q10) -> 33750 | N10: =(MIN(1,L10)*0.75*25000)+IF(L10>1,(MIN(2,L10-1)-1)*0.6*25000,0)+IF(L10>2,(L10-2)*25000*0.48,0) -> 0 | O10: =VLOOKUP($H10,PuertosLlegada!$B$2:$K$18,5,0) -> 0.75 | P10: =VLOOKUP($H10,PuertosLlegada!$B$2:$K$18,6,0) -> 0.6 | Q10: =VLOOKUP($H10,PuertosLlegada!$B$2:$K$18,7,0) -> 0.48 | R10: =IFERROR((E10/G10)*(T10),0) -> 32011.134 | S10: =IF(L10=0,0,VLOOKUP("SPD",PuertosLlegada!$B$2:$K$18,8,0)*E10/G10) -> 0 | T10: =VLOOKUP($H10,PuertosLlegada!$B$2:$K$18,8,0) -> 4.6 | U10: =IF(H10="PETROMIL",0.9*E10,0) -> 0 | V10: =IFERROR(VLOOKUP($H10,PuertosLlegada!$B$2:$K$18,10,0),0) -> 0.035 | W10: =IFERROR(VLOOKUP(H10,PuertosLlegada!$B$2:$N$18,13,0)*E10,0)*IF(U10>0,0,1) -> 0 | X10: =IFERROR(E10*IF(W10=0,0,0.035),0) -> 0
A11: =+COMPRAS!A11 -> I9 | C11: =+VLOOKUP(A11,COMPRAS!$A$2:$D$17,3,0) -> LIGHT OIL | D11: =+VLOOKUP($A11,COMPRAS!$A$2:$D$17,2,0) -> I9-BB Energy-LIGHT OIL-75-MBBL-MUSD$5,2875 | E11: =VLOOKUP(A11,COMPRAS!$A$2:$F$22,6,0) -> 75000 | F11: =VLOOKUP(A11, COMPRAS!$A$2:$N$21, 11, FALSE) -> 28 | G11: =VLOOKUP(A11, COMPRAS!$A$2:$N$21, 14, FALSE) -> 7.096 | H11: SPD | I11: TK-109_25K | J11: =IFERROR(__xludf.DUMMYFUNCTION("IFERROR(SUM(FILTER(PuertosLlegada!$E$2:$E$18, REGEXMATCH(PuertosLlegada!$C$2:$C$18, TEXTJOIN(""|"", TRUE, SPLIT(LLEGADA!I11, "", ""))))),0)"),25000) -> 25000 | K11: =IFERROR(IF((E11/J11)>0<1,1,(E11/J11)),0) -> 3 | L11: =IFERROR(IF(OR(H11="SPD",J11=0),0,E11/SUMIF(PuertosLlegada!$C$2:$C$18,"TK-109_25K",PuertosLlegada!$E$2:$E$18)),0) -> 0 | M11: =(MIN(1,K11)*J11*O11)+(IF(K11-1<0,0,MIN(K11-1,2))*J11*P11)+(IF(K11-2<0,0,K11-2)*J11*Q11) -> 60750 | N11: =(MIN(1,L11)*0.75*25000)+IF(L11>1,(MIN(2,L11-1)-1)*0.6*25000,0)+IF(L11>2,(L11-2)*25000*0.48,0) -> 0 | O11: =VLOOKUP($H11,PuertosLlegada!$B$2:$K$18,5,0) -> 0.75 | P11: =VLOOKUP($H11,PuertosLlegada!$B$2:$K$18,6,0) -> 0.6 | Q11: =VLOOKUP($H11,PuertosLlegada!$B$2:$K$18,7,0) -> 0.48 | R11: =IFERROR((E11/G11)*(T11),0) -> 48618.94 | S11: =IF(L11=0,0,VLOOKUP("SPD",PuertosLlegada!$B$2:$K$18,8,0)*E11/G11) -> 0 | T11: =VLOOKUP($H11,PuertosLlegada!$B$2:$K$18,8,0) -> 4.6 | U11: =IF(H11="PETROMIL",0.9*E11,0) -> 0 | V11: =IFERROR(VLOOKUP($H11,PuertosLlegada!$B$2:$K$18,10,0),0) -> 0.035 | W11: =IFERROR(VLOOKUP(H11,PuertosLlegada!$B$2:$N$18,13,0)*E11,0)*IF(U11>0,0,1) -> 0 | X11: =IFERROR(E11*IF(W11=0,0,0.035),0) -> 0
A12: =+COMPRAS!A12 -> I10 | C12: =+VLOOKUP(A12,COMPRAS!$A$2:$D$17,3,0) -> LIGHT OIL | D12: =+VLOOKUP($A12,COMPRAS!$A$2:$D$17,2,0) -> I10-GUNVOR Mediano-LIGHT OIL-15-MBBL-MUSD$1,065 | E12: =VLOOKUP(A12,COMPRAS!$A$2:$F$22,6,0) -> 15000 | F12: =VLOOKUP(A12, COMPRAS!$A$2:$N$21, 11, FALSE) -> 30 | G12: =VLOOKUP(A12, COMPRAS!$A$2:$N$21, 14, FALSE) -> 7.185 | H12: PALERMO | I12: PAL-7_80K | J12: =IFERROR(__xludf.DUMMYFUNCTION("IFERROR(SUM(FILTER(PuertosLlegada!$E$2:$E$18, REGEXMATCH(PuertosLlegada!$C$2:$C$18, TEXTJOIN(""|"", TRUE, SPLIT(LLEGADA!I12, "", ""))))),0)"),80000) -> 80000 | K12: =IFERROR(IF((E12/J12)>0<1,1,(E12/J12)),0) -> 0.1875 | L12: =IFERROR(IF(OR(H12="SPD",J12=0),0,E12/SUMIF(PuertosLlegada!$C$2:$C$18,"TK-109_25K",PuertosLlegada!$E$2:$E$18)),0) -> 0.6 | M12: =(MIN(1,K12)*J12*O12)+(IF(K12-1<0,0,MIN(K12-1,2))*J12*P12)+(IF(K12-2<0,0,K12-2)*J12*Q12) -> 22500 | N12: =(MIN(1,L12)*0.75*25000)+IF(L12>1,(MIN(2,L12-1)-1)*0.6*25000,0)+IF(L12>2,(L12-2)*25000*0.48,0) -> 11250 | O12: =VLOOKUP($H12,PuertosLlegada!$B$2:$K$18,5,0) -> 1.5 | P12: =VLOOKUP($H12,PuertosLlegada!$B$2:$K$18,6,0) -> 0.8 | Q12: =VLOOKUP($H12,PuertosLlegada!$B$2:$K$18,7,0) -> 0.8 | R12: =IFERROR((E12/G12)*(T12),0) -> 8350.7307 | S12: =IF(L12=0,0,VLOOKUP("SPD",PuertosLlegada!$B$2:$K$18,8,0)*E12/G12) -> 9603.3403 | T12: =VLOOKUP($H12,PuertosLlegada!$B$2:$K$18,8,0) -> 4 | U12: =IF(H12="PETROMIL",0.9*E12,0) -> 0 | V12: =IFERROR(VLOOKUP($H12,PuertosLlegada!$B$2:$K$18,10,0),0) -> 0 | W12: =IFERROR(VLOOKUP(H12,PuertosLlegada!$B$2:$N$18,13,0)*E12,0)*IF(U12>0,0,1) -> 27658.537 | X12: =IFERROR(E12*IF(W12=0,0,0.035),0) -> 525
A13: =+COMPRAS!A13 -> I11 | C13: =+VLOOKUP(A13,COMPRAS!$A$2:$D$17,3,0) -> LIGHT OIL | D13: =+VLOOKUP($A13,COMPRAS!$A$2:$D$17,2,0) -> I11-BB Energy-LIGHT OIL-200-MBBL-MUSD$13,6 | E13: =VLOOKUP(A13,COMPRAS!$A$2:$F$22,6,0) -> 200000 | F13: =VLOOKUP(A13, COMPRAS!$A$2:$N$21, 11, FALSE) -> 25 | G13: =VLOOKUP(A13, COMPRAS!$A$2:$N$21, 14, FALSE) -> 6.963 | H13: PETROMIL | I13: PET-1_30K, PET-2_30K | J13: =IFERROR(__xludf.DUMMYFUNCTION("IFERROR(SUM(FILTER(PuertosLlegada!$E$2:$E$18, REGEXMATCH(PuertosLlegada!$C$2:$C$18, TEXTJOIN(""|"", TRUE, SPLIT(LLEGADA!I13, "", ""))))),0)"),60000) -> 60000 | K13: =IFERROR(IF((E13/J13)>0<1,1,(E13/J13)),0) -> 3.3333333 | L13: =IFERROR(IF(OR(H13="SPD",J13=0),0,E13/SUMIF(PuertosLlegada!$C$2:$C$18,"TK-109_25K",PuertosLlegada!$E$2:$E$18)),0) -> 8 | M13: =(MIN(1,K13)*J13*O13)+(IF(K13-1<0,0,MIN(K13-1,2))*J13*P13)+(IF(K13-2<0,0,K13-2)*J13*Q13) -> 265000 | N13: =(MIN(1,L13)*0.75*25000)+IF(L13>1,(MIN(2,L13-1)-1)*0.6*25000,0)+IF(L13>2,(L13-2)*25000*0.48,0) -> 105750 | O13: =VLOOKUP($H13,PuertosLlegada!$B$2:$K$18,5,0) -> 1.75 | P13: =VLOOKUP($H13,PuertosLlegada!$B$2:$K$18,6,0) -> 0.8 | Q13: =VLOOKUP($H13,PuertosLlegada!$B$2:$K$18,7,0) -> 0.8 | R13: =IFERROR((E13/G13)*(T13),0) -> 114893.01 | S13: =IF(L13=0,0,VLOOKUP("SPD",PuertosLlegada!$B$2:$K$18,8,0)*E13/G13) -> 132126.96 | T13: =VLOOKUP($H13,PuertosLlegada!$B$2:$K$18,8,0) -> 4 | U13: =IF(H13="PETROMIL",0.9*E13,0) -> 180000 | V13: =IFERROR(VLOOKUP($H13,PuertosLlegada!$B$2:$K$18,10,0),0) -> 0 | W13: =IFERROR(VLOOKUP(H13,PuertosLlegada!$B$2:$N$18,13,0)*E13,0)*IF(U13>0,0,1) -> 0 | X13: =IFERROR(E13*IF(W13=0,0,0.035),0) -> 0
A14: =+COMPRAS!A14 -> I12 | C14: =+VLOOKUP(A14,COMPRAS!$A$2:$D$17,3,0) -> LIGHT OIL | D14: =+VLOOKUP($A14,COMPRAS!$A$2:$D$17,2,0) -> I12-GUNVOR-LIGHT OIL-50-MBBL-MUSD$3,55 | E14: =VLOOKUP(A14,COMPRAS!$A$2:$F$22,6,0) -> 50000 | F14: =VLOOKUP(A14, COMPRAS!$A$2:$N$21, 11, FALSE) -> 30 | G14: =VLOOKUP(A14, COMPRAS!$A$2:$N$21, 14, FALSE) -> 7.185 | H14: SPD | I14: TK-109_25K | J14: =IFERROR(__xludf.DUMMYFUNCTION("IFERROR(SUM(FILTER(PuertosLlegada!$E$2:$E$18, REGEXMATCH(PuertosLlegada!$C$2:$C$18, TEXTJOIN(""|"", TRUE, SPLIT(LLEGADA!I14, "", ""))))),0)"),25000) -> 25000 | K14: =IFERROR(IF((E14/J14)>0<1,1,(E14/J14)),0) -> 2 | L14: =IFERROR(IF(OR(H14="SPD",J14=0),0,E14/SUMIF(PuertosLlegada!$C$2:$C$18,"TK-109_25K",PuertosLlegada!$E$2:$E$18)),0) -> 0 | M14: =(MIN(1,K14)*J14*O14)+(IF(K14-1<0,0,MIN(K14-1,2))*J14*P14)+(IF(K14-2<0,0,K14-2)*J14*Q14) -> 33750 | N14: =(MIN(1,L14)*0.75*25000)+IF(L14>1,(MIN(2,L14-1)-1)*0.6*25000,0)+IF(L14>2,(L14-2)*25000*0.48,0) -> 0 | O14: =VLOOKUP($H14,PuertosLlegada!$B$2:$K$18,5,0) -> 0.75 | P14: =VLOOKUP($H14,PuertosLlegada!$B$2:$K$18,6,0) -> 0.6 | Q14: =VLOOKUP($H14,PuertosLlegada!$B$2:$K$18,7,0) -> 0.48 | R14: =IFERROR((E14/G14)*(T14),0) -> 32011.134 | S14: =IF(L14=0,0,VLOOKUP("SPD",PuertosLlegada!$B$2:$K$18,8,0)*E14/G14) -> 0 | T14: =VLOOKUP($H14,PuertosLlegada!$B$2:$K$18,8,0) -> 4.6 | U14: =IF(H14="PETROMIL",0.9*E14,0) -> 0 | V14: =IFERROR(VLOOKUP($H14,PuertosLlegada!$B$2:$K$18,10,0),0) -> 0.035 | W14: =IFERROR(VLOOKUP(H14,PuertosLlegada!$B$2:$N$18,13,0)*E14,0)*IF(U14>0,0,1) -> 0 | X14: =IFERROR(E14*IF(W14=0,0,0.035),0) -> 0
H15: SPD | I15: TK-109_25K | J15: =IFERROR(__xludf.DUMMYFUNCTION("IFERROR(SUM(FILTER(PuertosLlegada!$E$2:$E$18, REGEXMATCH(PuertosLlegada!$C$2:$C$18, TEXTJOIN(""|"", TRUE, SPLIT(LLEGADA!I15, "", ""))))),0)"),25000) -> 25000 | K15: =IFERROR(IF((E15/J15)>0<1,1,(E15/J15)),0) -> 0 | L15: =IFERROR(IF(OR(H15="SPD",J15=0),0,E15/SUMIF(PuertosLlegada!$C$2:$C$18,"TK-109_25K",PuertosLlegada!$E$2:$E$18)),0) -> 0 | M15: =(MIN(1,K15)*J15*O15)+(IF(K15-1<0,0,MIN(K15-1,2))*J15*P15)+(IF(K15-2<0,0,K15-2)*J15*Q15) -> 0 | N15: =(MIN(1,L15)*0.75*25000)+IF(L15>1,(MIN(2,L15-1)-1)*0.6*25000,0)+IF(L15>2,(L15-2)*25000*0.48,0) -> 0 | O15: =VLOOKUP($H15,PuertosLlegada!$B$2:$K$18,5,0) -> 0.75 | P15: =VLOOKUP($H15,PuertosLlegada!$B$2:$K$18,6,0) -> 0.6 | Q15: =VLOOKUP($H15,PuertosLlegada!$B$2:$K$18,7,0) -> 0.48 | R15: =IFERROR((E15/G15)*(T15),0) -> 0 | S15: =IF(L15=0,0,VLOOKUP("SPD",PuertosLlegada!$B$2:$K$18,8,0)*E15/G15) -> 0 | T15: =VLOOKUP($H15,PuertosLlegada!$B$2:$K$18,8,0) -> 4.6 | U15: =IF(H15="PETROMIL",0.9*E15,0) -> 0 | V15: =IFERROR(VLOOKUP($H15,PuertosLlegada!$B$2:$K$18,10,0),0) -> 0.035 | W15: =IFERROR(VLOOKUP(H15,PuertosLlegada!$B$2:$N$18,13,0)*E15,0)*IF(U15>0,0,1) -> 0 | X15: =IFERROR(E15*IF(W15=0,0,0.035),0) -> 0
H16: PUERTO_BAHIA | I16: BAHIA-1_300K | J16: =IFERROR(__xludf.DUMMYFUNCTION("IFERROR(SUM(FILTER(PuertosLlegada!$E$2:$E$18, REGEXMATCH(PuertosLlegada!$C$2:$C$18, TEXTJOIN(""|"", TRUE, SPLIT(LLEGADA!I16, "", ""))))),0)"),300000) -> 300000 | K16: =IFERROR(IF((E16/J16)>0<1,1,(E16/J16)),0) -> 0 | L16: =IFERROR(IF(OR(H16="SPD",J16=0),0,E16/SUMIF(PuertosLlegada!$C$2:$C$18,"TK-109_25K",PuertosLlegada!$E$2:$E$18)),0) -> 0 | M16: =(MIN(1,K16)*J16*O16)+(IF(K16-1<0,0,MIN(K16-1,2))*J16*P16)+(IF(K16-2<0,0,K16-2)*J16*Q16) -> 0 | N16: =(MIN(1,L16)*0.75*25000)+IF(L16>1,(MIN(2,L16-1)-1)*0.6*25000,0)+IF(L16>2,(L16-2)*25000*0.48,0) -> 0 | O16: =VLOOKUP($H16,PuertosLlegada!$B$2:$K$18,5,0) -> 1.3 | P16: =VLOOKUP($H16,PuertosLlegada!$B$2:$K$18,6,0) -> 0.8 | Q16: =VLOOKUP($H16,PuertosLlegada!$B$2:$K$18,7,0) -> 0.8 | R16: =IFERROR((E16/G16)*(T16),0) -> 0 | S16: =IF(L16=0,0,VLOOKUP("SPD",PuertosLlegada!$B$2:$K$18,8,0)*E16/G16) -> 0 | T16: =VLOOKUP($H16,PuertosLlegada!$B$2:$K$18,8,0) -> 3.5 | U16: =IF(H16="PETROMIL",0.9*E16,0) -> 0 | V16: =IFERROR(VLOOKUP($H16,PuertosLlegada!$B$2:$K$18,10,0),0) -> 0 | W16: =IFERROR(VLOOKUP(H16,PuertosLlegada!$B$2:$N$18,13,0)*E16,0)*IF(U16>0,0,1) -> 0 | X16: =IFERROR(E16*IF(W16=0,0,0.035),0) -> 0
H17: SPD | I17: TK-109_25K | J17: =IFERROR(__xludf.DUMMYFUNCTION("IFERROR(SUM(FILTER(PuertosLlegada!$E$2:$E$18, REGEXMATCH(PuertosLlegada!$C$2:$C$18, TEXTJOIN(""|"", TRUE, SPLIT(LLEGADA!I17, "", ""))))),0)"),25000) -> 25000 | K17: =IFERROR(IF((E17/J17)>0<1,1,(E17/J17)),0) -> 0 | L17: =IFERROR(IF(OR(H17="SPD",J17=0),0,E17/SUMIF(PuertosLlegada!$C$2:$C$18,"TK-109_25K",PuertosLlegada!$E$2:$E$18)),0) -> 0 | M17: =(MIN(1,K17)*J17*O17)+(IF(K17-1<0,0,MIN(K17-1,2))*J17*P17)+(IF(K17-2<0,0,K17-2)*J17*Q17) -> 0 | N17: =(MIN(1,L17)*0.75*25000)+IF(L17>1,(MIN(2,L17-1)-1)*0.6*25000,0)+IF(L17>2,(L17-2)*25000*0.48,0) -> 0 | O17: =VLOOKUP($H17,PuertosLlegada!$B$2:$K$18,5,0) -> 0.75 | P17: =VLOOKUP($H17,PuertosLlegada!$B$2:$K$18,6,0) -> 0.6 | Q17: =VLOOKUP($H17,PuertosLlegada!$B$2:$K$18,7,0) -> 0.48 | R17: =IFERROR((E17/G17)*(T17),0) -> 0 | S17: =IF(L17=0,0,VLOOKUP("SPD",PuertosLlegada!$B$2:$K$18,8,0)*E17/G17) -> 0 | T17: =VLOOKUP($H17,PuertosLlegada!$B$2:$K$18,8,0) -> 4.6 | U17: =IF(H17="PETROMIL",0.9*E17,0) -> 0 | V17: =IFERROR(VLOOKUP($H17,PuertosLlegada!$B$2:$K$18,10,0),0) -> 0.035 | W17: =IFERROR(VLOOKUP(H17,PuertosLlegada!$B$2:$N$18,13,0)*E17,0)*IF(U17>0,0,1) -> 0 | X17: =IFERROR(E17*IF(W17=0,0,0.035),0) -> 0

Sheet COMPRAS
A1: ID Transacción | B1: CONTRATO | C1: PRODUCTO | D1: Proveedor | E1: Spread on Brent | F1: Volumen a Comprar (BPD) | G1: Precio de Compra CALCULADO (USD/BPD) | H1: Movimiento | I1: Flete Maritimo | J1: Valor Flete | K1: CALIDAD API | L1: SPG | M1: DENSIDAD (S.I) | N1: FC bbl/Ton | O1: %AZUFRE | P1: Viscosidad Cst | Q1: Water by Distillation % v/v
A2: I1 | B2: =A2&"-"&D2&"-"&C2&"-"&F2/1000&"-"&"MBBL"&"-MUSD$"&(G2/1000000) -> I1-GUNVOR Mediano-LIGHT OIL-100-MBBL-MUSD$7 | C2: LIGHT OIL | D2: GUNVOR Mediano | E2: 2 | F2: 100000 | G2: =+(BRENT+E2)*F2 -> 7000000 | H2: Importación | I2: 3.5 | J2: =+I2*F2 -> 350000 | K2: 32 | L2: =+(141.5/(K2+131.5)) -> 0.86544343 | M2: =+L2*999.016 -> 864.59183 | N2: =VLOOKUP(K2,PuertosLlegada!$A$32:$B$122,2,0) -> 7.274 | O2: 0.005 | P2: 100 | Q2: 0.003
A3: I2 | B3: =A3&"-"&D3&"-"&C3&"-"&F3/1000&"-"&"MBBL"&"-MUSD$"&(G3/1000000) -> I2-GUNVOR Mediano-LIGHT OIL-100-MBBL-MUSD$7 | C3: LIGHT OIL | D3: GUNVOR Mediano | E3: 2 | F3: 100000 | G3: =+(BRENT+E3)*F3 -> 7000000 | H3: Importación | I3: 3.5 | J3: =+I3*F3 -> 350000 | K3: 32 | L3: =+(141.5/(K3+131.5)) -> 0.86544343 | M3: =+L3*999.016 -> 864.59183 | N3: =VLOOKUP(K3,PuertosLlegada!$A$32:$B$122,2,0) -> 7.274 | O3: 0.005 | P3: 100 | Q3: 0.003
A4: E1 | B4: =A4&"-"&D4&"-"&C4&"-"&F4/1000&"-"&"MBBL"&"-MUSD$"&(G4/1000000) -> E1-Ecopetrol (Exportación-Flete asumido cliente)-FUEL OIL-100-MBBL-MUSD$7 | C4: FUEL OIL | D4: Ecopetrol (Exportación-Flete asumido cliente) | E4: 2 | F4: 100000 | G4: =+(BRENT+E4)*F4 -> 7000000 | H4: Exportación | I4: 0 | J4: =+I4*F4 -> 0 | K4: 16 | L4: =+(141.5/(K4+131.5)) -> 0.95932203 | M4: =+L4*999.016 -> 958.37806 | N4: =VLOOKUP(K4,PuertosLlegada!$A$32:$B$122,2,0) -> 6.562 | O4: 0.005 | P4: 100 | Q4: 0.003
A5: I3 | B5: =A5&"-"&D5&"-"&C5&"-"&F5/1000&"-"&"MBBL"&"-MUSD$"&(G5/1000000) -> I3-GUNVOR Mediano-LIGHT OIL-100-MBBL-MUSD$7 | C5: LIGHT OIL | D5: GUNVOR Mediano | E5: 2 | F5: 100000 | G5: =+(BRENT+E5)*F5 -> 7000000 | H5: Importación | I5: 3.5 | J5: =+I5*F5 -> 350000 | K5: 32 | L5: =+(141.5/(K5+131.5)) -> 0.86544343 | M5: =+L5*999.016 -> 864.59183 | N5: =VLOOKUP(K5,PuertosLlegada!$A$32:$B$122,2,0) -> 7.274 | O5: 0.005 | P5: 100 | Q5: 0.003
A6: I4 | B6: =A6&"-"&D6&"-"&C6&"-"&F6/1000&"-"&"MBBL"&"-MUSD$"&(G6/1000000) -> I4-GUNVOR Mediano-LIGHT OIL-100-MBBL-MUSD$7 | C6: LIGHT OIL | D6: GUNVOR Mediano | E6: 2 | F6: 100000 | G6: =+(BRENT+E6)*F6 -> 7000000 | H6: Importación | I6: 3.5 | J6: =+I6*F6 -> 350000 | K6: 32 | L6: =+(141.5/(K6+131.5)) -> 0.86544343 | M6: =+L6*999.016 -> 864.59183 | N6: =VLOOKUP(K6,PuertosLlegada!$A$32:$B$122,2,0) -> 7.274 | O6: 0.005 | P6: 100 | Q6: 0.003
A7: I5 | B7: =A7&"-"&D7&"-"&C7&"-"&F7/1000&"-"&"MBBL"&"-MUSD$"&(G7/1000000) -> I5-GUNVOR-LIGHT OIL-35-MBBL-MUSD$2,45 | C7: LIGHT OIL | D7: GUNVOR | E7: 2 | F7: 35000 | G7: =+(BRENT+E7)*F7 -> 2450000 | H7: Importación | I7: 4 | J7: =+I7*F7 -> 140000 | K7: 32 | L7: =+(141.5/(K7+131.5)) -> 0.86544343 | M7: =+L7*999.016 -> 864.59183 | N7: =VLOOKUP(K7,PuertosLlegada!$A$32:$B$122,2,0) -> 7.274 | O7: 0.005 | P7: 100 | Q7: 0.003
A8: I6 | B8: =A8&"-"&D8&"-"&C8&"-"&F8/1000&"-"&"MBBL"&"-MUSD$"&(G8/1000000) -> I6-BB Energy-LIGHT OIL-20-MBBL-MUSD$1,44 | C8: LIGHT OIL | D8: BB Energy | E8: 4 | F8: 20000 | G8: =+(BRENT+E8)*F8 -> 1440000 | H8: Importación | I8: 5 | J8: =+I8*F8 -> 100000 | K8: 33 | L8: =+(141.5/(K8+131.5)) -> 0.86018237 | M8: =+L8*999.016 -> 859.33595 | N8: =VLOOKUP(K8,PuertosLlegada!$A$32:$B$122,2,0) -> 7.319 | O8: 0.005 | P8: 100 | Q8: 0.003
A9: I7 | B9: =A9&"-"&D9&"-"&C9&"-"&F9/1000&"-"&"MBBL"&"-MUSD$"&(G9/1000000) -> I7-GUNVOR Mediano-LIGHT OIL-300-MBBL-MUSD$20,4 | C9: LIGHT OIL | D9: GUNVOR Mediano | E9: 0 | F9: 300000 | G9: =+(BRENT+E9)*F9 -> 20400000 | H9: Importación | I9: 2 | J9: =+I9*F9 -> 600000 | K9: 21 | L9: =+(141.5/(K9+131.5)) -> 0.92786885 | M9: =+L9*999.016 -> 926.95583 | N9: =VLOOKUP(K9,PuertosLlegada!$A$32:$B$122,2,0) -> 6.785 | O9: 0.005 | P9: 100 | Q9: 0.003
A10: I8 | B10: =A10&"-"&D10&"-"&C10&"-"&F10/1000&"-"&"MBBL"&"-MUSD$"&(G10/1000000) -> I8-GUNVOR-LIGHT OIL-50-MBBL-MUSD$3,5 | C10: LIGHT OIL | D10: GUNVOR | E10: 2 | F10: 50000 | G10: =+(BRENT+E10)*F10 -> 3500000 | H10: Importación | I10: 4 | J10: =+I10*F10 -> 200000 | K10: 30 | L10: =+(141.5/(K10+131.5)) -> 0.87616099 | M10: =+L10*999.016 -> 875.29885 | N10: =VLOOKUP(K10,PuertosLlegada!$A$32:$B$122,2,0) -> 7.185 | O10: 0.005 | P10: 100 | Q10: 0.003
A11: I9 | B11: =A11&"-"&D11&"-"&C11&"-"&F11/1000&"-"&"MBBL"&"-MUSD$"&(G11/1000000) -> I9-BB Energy-LIGHT OIL-75-MBBL-MUSD$5,2875 | C11: LIGHT OIL | D11: BB Energy | E11: 2.5 | F11: 75000 | G11: =+(BRENT+E11)*F11 -> 5287500 | H11: Importación | I11: 4 | J11: =+I11*F11 -> 300000 | K11: 28 | L11: =+(141.5/(K11+131.5)) -> 0.88714734 | M11: =+L11*999.016 -> 886.27438 | N11: =VLOOKUP(K11,PuertosLlegada!$A$32:$B$122,2,0) -> 7.096 | O11: 0.005 | P11: 100 | Q11: 0.003
A12: I10 | B12: =A12&"-"&D12&"-"&C12&"-"&F12/1000&"-"&"MBBL"&"-MUSD$"&(G12/1000000) -> I10-GUNVOR Mediano-LIGHT OIL-15-MBBL-MUSD$1,065 | C12: LIGHT OIL | D12: GUNVOR Mediano | E12: 3 | F12: 15000 | G12: =+(BRENT+E12)*F12 -> 1065000 | H12: Importación | I12: 5 | J12: =+I12*F12 -> 75000 | K12: 30 | L12: =+(141.5/(K12+131.5)) -> 0.87616099 | M12: =+L12*999.016 -> 875.29885 | N12: =VLOOKUP(K12,PuertosLlegada!$A$32:$B$122,2,0) -> 7.185 | O12: 0.005 | P12: 100 | Q12: 0.003
A13: I11 | B13: =A13&"-"&D13&"-"&C13&"-"&F13/1000&"-"&"MBBL"&"-MUSD$"&(G13/1000000) -> I11-BB Energy-LIGHT OIL-200-MBBL-MUSD$13,6 | C13: LIGHT OIL | D13: BB Energy | E13: 0 | F13: 200000 | G13: =+(BRENT+E13)*F13 -> 13600000 | H13: Importación | I13: 3 | J13: =+I13*F13 -> 600000 | K13: 25 | L13: =+(141.5/(K13+131.5)) -> 0.90415335 | M13: =+L13*999.016 -> 903.26367 | N13: =VLOOKUP(K13,PuertosLlegada!$A$32:$B$122,2,0) -> 6.963 | O13: 0.005 | P13: 100 | Q13: 0.003
A14: I12 | B14: =A14&"-"&D14&"-"&C14&"-"&F14/1000&"-"&"MBBL"&"-MUSD$"&(G14/1000000) -> I12-GUNVOR-LIGHT OIL-50-MBBL-MUSD$3,55 | C14: LIGHT OIL | D14: GUNVOR | E14: 3 | F14: 50000 | G14: =+(BRENT+E14)*F14 -> 3550000 | H14: Importación | I14: 4 | J14: =+I14*F14 -> 200000 | K14: 30 | L14: =+(141.5/(K14+131.5)) -> 0.87616099 | M14: =+L14*999.016 -> 875.29885 | N14: =VLOOKUP(K14,PuertosLlegada!$A$32:$B$122,2,0) -> 7.185 | O14: 0.005 | P14: 100 | Q14: 0.003
B15: =A15&"-"&D15&"-"&C15&"-"&F15/1000&"-"&"MBBL"&"-MUSD$"&(G15/1000000) -> ---0-MBBL-MUSD$0
B16: =A16&"-"&D16&"-"&C16&"-"&F16/1000&"-"&"MBBL"&"-MUSD$"&(G16/1000000) -> ---0-MBBL-MUSD$0 | G16: =+(BRENT+E16)*F16 -> 0
B17: =A17&"-"&D17&"-"&C17&"-"&F17/1000&"-"&"MBBL"&"-MUSD$"&(G17/1000000) -> ---0-MBBL-MUSD$0 | G17: =+(BRENT+E17)*F17 -> 0

Sheet PuertosLlegada
A1: Ciudad | B1: PUERTO | C1: # TANQUE | D1: Producto | E1: VOLUMEN ALMACENAMIENTO bbl | F1: 1ra Vuelta | G1: 2da Vuelta | H1: 3ra Vuelta | I1: OPER PORTUARIO | J1: USO A LA CARGA | K1: Costo Ingreso CZF Bbl | L1: Requiere Transporte a Refineria | M1: COP/Gln | N1: USD/Bbl | O1: Costo Ingreso CZF | P1: 1ra Vuelta | Q1: 2da Vuelta | R1: 3ra Vuelta | S1: Toneladas /mes
A2: Cartagena | B2: SPD | C2: TK-109_25K | D2: Crudo | E2: 25000 | F2: 0.75 | G2: 0.6 | H2: 0.48 | I2: 4.6 | K2: 0.035 | L2: NO | M2: 0 | N2: =M2*42/ECONOMICOS!$B$3 -> 0
A3: Cartagena | B3: SPD | C3: TK-110_25K | D3: Crudo | E3: 25000 | F3: 0.75 | G3: 0.6 | H3: 0.48 | I3: 4.6 | K3: 0.035 | L3: NO | M3: 0 | N3: =M3*42/TRM -> 0
A4: Cartagena | B4: SPD | C4: TK-102_5K | D4: Crudo | E4: 5000 | F4: 0.75 | G4: 0.6 | H4: 0.48 | I4: 4.6 | K4: 0.035 | L4: NO | M4: 0 | N4: =M4*42/TRM -> 0
A5: Cartagena | B5: SPD | C5: TK-101_5K | D5: Crudo | E5: 5000 | F5: 0.75 | G5: 0.6 | H5: 0.48 | I5: 4.6 | K5: 0.035 | L5: NO | M5: 0 | N5: =M5*42/TRM -> 0
A6: Cartagena | B6: SPD | C6: TK-107_30K | D6: Crudo | E6: 30000 | F6: 0.75 | G6: 0.6 | H6: 0.48 | I6: 4.6 | K6: 0.035 | L6: NO | M6: 0 | N6: =M6*42/TRM -> 0
A7: Cartagena | B7: SPD | C7: TK-105_30k | D7: Crudo | E7: 30000 | F7: 0.75 | G7: 0.6 | H7: 0.48 | I7: 4.6 | K7: 0.035 | L7: NO | M7: 0 | N7: =M7*42/TRM -> 0
A8: Barranquilla | B8: PALERMO | C8: PAL-1_168K | D8: Crudo | E8: 168000 | F8: 1.5 | G8: 0.8 | H8: 0.8 | I8: 4 | J8: 0 | L8: Si | M8: 180 | N8: =M8*42/TRM -> 1.8439024 | O8: 0.035 | P8: 0.75 | Q8: 0.6 | R8: 0.48
